Workbook

Sheet ESF
B2: JELCOM SOLUCIONES EMPRESARIALES SAS
B3: NIT. 901360819
B4: ESTADO DE SITUACIÓN FINANCIERA A:
B5: (Cifras expresadas en pesos colombianos - M$)
B7: ACTIVO | D7: NOTA | F7: 31.01.2026 | H7: 31.12.2025 | I7: 30.11.2025 | J7: 31.10.2025 | K7: 30.09.2025 | L7: 31.08.2025 | M7: 31.07.2025 | N7: 30.06.2025 | O7: 31.05.2025 | P7: 30.04.2025 | Q7: 31.03.2025 | R7: 28.02.2025 | S7: 31.01.2025 | U7: 31.12.2024 | V7: 30.11.2024 | W7: 31.10.2024 | X7: 30.09.2024 | Y7: 31.08.2024 | Z7: 31.07.2024 | AA7: 30.06.2024 | AB7: 31.05.2024 | AC7: 30.04.2024 | AD7: 31.03.2024 | AE7: 29.02.2023 | AF7: 31.01.2024 | AH7: 31.12.2023 | AI7: 30.11.2023 | AJ7: 31.10.2023 | AK7: 30.09.2023 | AL7: 31.08.2023 | AM7: 30.07.2023 | AN7: 30.06.2023 | AO7: 31.05.2023 | AP7: 31.04.2023 | AQ7: 31.03.2023 | AR7: 28.02.2023 | AS7: 31.01.2023 | AU7: 31.12.2022 | AV7: 30.11.2022 | AW7: 31.10.2022 | AX7: 30.09.2022 | AY7: 31.08.2022 | AZ7: 31.07.2022 | BA7: 30.06.2022 | BB7: 31.05.2022 | BC7: 31.04.2022 | BD7: 31.03.2022 | BE7: 28.02.2022 | BF7: 31.01.2022 | BH7: 31.12.2021 | BI7: 30.09.2021 | BJ7: 30.08.2021 | BK7: 30.07.2021 | BL7: 30.06.2021 | BM7: 01.05.2021 | BO7: 31.12.2020
B9: Corriente
B10: Efectivo y Equivalentes al Efectivo | D10: 4 | F10: =+'NOTAS ESF'!B10 -> 26352599 | H10: =+'NOTAS ESF'!D10 -> 65794723 | I10: =+'NOTAS ESF'!E10 -> 29244298 | J10: =+'NOTAS ESF'!F10 -> 21098136 | K10: =+'NOTAS ESF'!G10 -> 14529916 | L10: =+'NOTAS ESF'!H10 -> 10355964 | M10: =+'NOTAS ESF'!I10 -> 11927408 | N10: =+'NOTAS ESF'!J10 -> 5739207.5 | O10: =+'NOTAS ESF'!K10 -> 16777658 | ... S10: =+'NOTAS ESF'!O10 -> 7199659.9 | U10: =+'NOTAS ESF'!Q10 -> 5382680.7 | V10: =+'NOTAS ESF'!R10 -> 5032561 | W10: =+'NOTAS ESF'!S10 -> 4883116.8 | X10: =+'NOTAS ESF'!T10 -> 4072200.8 | Y10: =+'NOTAS ESF'!U10 -> -4649353.1 | Z10: =+'NOTAS ESF'!V10 -> -5795604.9 | AA10: =+'NOTAS ESF'!W10 -> -3994354.1 | AB10: =+'NOTAS ESF'!X10 -> -1573955.3 | ... AF10: =+'NOTAS ESF'!AB10 -> 6342950.9 | AH10: =+'NOTAS ESF'!AD10 -> 1846377.4 | AI10: =+'NOTAS ESF'!AE10 -> -16503757 | AJ10: =+'NOTAS ESF'!AF10 -> -15088454 | AK10: =+'NOTAS ESF'!AG10 -> -16610194 | AL10: =+'NOTAS ESF'!AH10 -> -16113342 | AM10: =+'NOTAS ESF'!AI10 -> -13926093 | AN10: =+'NOTAS ESF'!AJ10 -> -15129335 | AO10: =+'NOTAS ESF'!AK10 -> -12473354 | ... AS10: =+'NOTAS ESF'!AO10 -> -4863415.3 | AU10: =+'NOTAS ESF'!AQ10 -> 3821900.2 | AV10: =+'NOTAS ESF'!AR10 -> 89923 | AW10: =+'NOTAS ESF'!AS10 -> 3267146 | AX10: =+'NOTAS ESF'!AT10 -> 1261066 | AY10: =+'NOTAS ESF'!AU10 -> 102040 | AZ10: =+'NOTAS ESF'!AV10 -> 0 | BA10: =+'NOTAS ESF'!AW10 -> 0 | BB10: =+'NOTAS ESF'!AX10 -> 0 | ... BF10: =+'NOTAS ESF'!BB10 -> 0 | BH10: =+'NOTAS ESF'!BD10 -> 15221800 | BI10: =+'NOTAS ESF'!BE10 -> 0 | BJ10: =+'NOTAS ESF'!BF10 -> 0 | BK10: =+'NOTAS ESF'!BG10 -> 0 | BL10: =+'NOTAS ESF'!BH10 -> 0 | BM10: =+'NOTAS ESF'!BI10 -> 0 | BO10: =+'NOTAS ESF'!BK10 -> 2000000
B11: Instrumentos Financieros Cuentas Por Cobrar | D11: 5 | F11: =+'NOTAS ESF'!B14 -> 60550558 | H11: =+'NOTAS ESF'!D14 -> 26355626 | I11: =+'NOTAS ESF'!E14 -> 63694677 | J11: =+'NOTAS ESF'!F14 -> 46536961 | K11: =+'NOTAS ESF'!G14 -> 53380639 | L11: =+'NOTAS ESF'!H14 -> 39619796 | M11: =+'NOTAS ESF'!I14 -> 35652593 | N11: =+'NOTAS ESF'!J14 -> 33989755 | O11: =+'NOTAS ESF'!K14 -> 31431872 | ... S11: =+'NOTAS ESF'!O14 -> 8143514.7 | U11: =+'NOTAS ESF'!Q14 -> 15258879 | V11: =+'NOTAS ESF'!R14 -> 14415869 | W11: =+'NOTAS ESF'!S14 -> 14986890 | X11: =+'NOTAS ESF'!T14 -> 23162180 | Y11: =+'NOTAS ESF'!U14 -> 28904093 | Z11: =+'NOTAS ESF'!V14 -> 29247383 | AA11: =+'NOTAS ESF'!W14 -> 25029313 | AB11: =+'NOTAS ESF'!X14 -> 33443093 | ... AF11: =+'NOTAS ESF'!AB14 -> 21982196 | AH11: =+'NOTAS ESF'!AD14 -> 20841140 | AI11: =+'NOTAS ESF'!AE14 -> 4765667.3 | AJ11: =+'NOTAS ESF'!AF14 -> 4380307.3 | AK11: =+'NOTAS ESF'!AG14 -> 3878887.7 | AL11: =+'NOTAS ESF'!AH14 -> 3706628 | AM11: =+'NOTAS ESF'!AI14 -> 3427628 | AN11: =+'NOTAS ESF'!AJ14 -> 3133668 | AO11: =+'NOTAS ESF'!AK14 -> 2794188 | ... BM11: =+'NOTAS ESF'!BI14 -> 0 | BO11: =+'NOTAS ESF'!BK14 -> 0
B12: Total | F12: =SUM(F10:F11) -> 86903157 | H12: =SUM(H10:H11) -> 92150349 | I12: =SUM(I10:I11) -> 92938975 | J12: =SUM(J10:J11) -> 67635097 | K12: =SUM(K10:K11) -> 67910555 | L12: =SUM(L10:L11) -> 49975760 | M12: =SUM(M10:M11) -> 47580001 | N12: =SUM(N10:N11) -> 39728962 | O12: =SUM(O10:O11) -> 48209530 | ... S12: =SUM(S10:S11) -> 15343175 | U12: =SUM(U10:U11) -> 20641560 | V12: =SUM(V10:V11) -> 19448430 | W12: =SUM(W10:W11) -> 19870007 | X12: =SUM(X10:X11) -> 27234381 | Y12: =SUM(Y10:Y11) -> 24254740 | Z12: =SUM(Z10:Z11) -> 23451778 | AA12: =SUM(AA10:AA11) -> 21034959 | AB12: =SUM(AB10:AB11) -> 31869138 | ... AF12: =SUM(AF10:AF11) -> 28325147 | AH12: =SUM(AH10:AH11) -> 22687518 | AI12: =SUM(AI10:AI11) -> -11738090 | AJ12: =SUM(AJ10:AJ11) -> -10708147 | AK12: =SUM(AK10:AK11) -> -12731306 | AL12: =SUM(AL10:AL11) -> -12406714 | AM12: =SUM(AM10:AM11) -> -10498465 | AN12: =SUM(AN10:AN11) -> -11995667 | AO12: =SUM(AO10:AO11) -> -9679165.7 | ... AS12: =SUM(AS10:AS11) -> -3098320.3 | AU12: =SUM(AU10:AU11) -> 6365748.2 | AV12: =SUM(AV10:AV11) -> 887662 | AW12: =SUM(AW10:AW11) -> 40142491 | AX12: =SUM(AX10:AX11) -> 54084791 | AY12: =SUM(AY10:AY11) -> 31179818 | AZ12: =SUM(AZ10:AZ11) -> 17206089 | BA12: =SUM(BA10:BA11) -> 17206089 | BB12: =SUM(BB10:BB11) -> 17206089 | ... BF12: =SUM(BF10:BF11) -> 11686588 | BH12: =SUM(BH10:BH11) -> 15723388 | BI12: =SUM(BI10:BI11) -> 0 | BJ12: =SUM(BJ10:BJ11) -> 0 | BK12: =SUM(BK10:BK11) -> 0 | BL12: =SUM(BL10:BL11) -> 0 | BM12: =SUM(BM10:BM11) -> 0 | BO12: =SUM(BO10:BO11) -> 2000000
B14: No corriente
B15: Propiedad Planta y Equipo | D15: 6 | F15: =+'NOTAS ESF'!B61 -> 17386530 | H15: =+'NOTAS ESF'!D61 -> 17386530 | I15: =+'NOTAS ESF'!E61 -> 17386530 | J15: =+'NOTAS ESF'!F61 -> 17386530 | K15: =+'NOTAS ESF'!G61 -> 17386530 | L15: =+'NOTAS ESF'!H61 -> 17386530 | M15: =+'NOTAS ESF'!I61 -> 17386530 | N15: =+'NOTAS ESF'!J61 -> 17386530 | O15: =+'NOTAS ESF'!K61 -> 17386530 | ... S15: =+'NOTAS ESF'!O61 -> 17386530 | U15: =+'NOTAS ESF'!Q61 -> 17386530 | V15: =+'NOTAS ESF'!R61 -> 17386530 | W15: =+'NOTAS ESF'!S61 -> 17386530 | X15: =+'NOTAS ESF'!T61 -> 17386530 | Y15: =+'NOTAS ESF'!U61 -> 17386530 | Z15: =+'NOTAS ESF'!V61 -> 17386530 | AA15: =+'NOTAS ESF'!W61 -> 17386530 | AB15: =+'NOTAS ESF'!X61 -> 17386530 | ... AF15: =+'NOTAS ESF'!AB61 -> 17386530 | AH15: =+'NOTAS ESF'!AD61 -> 17386530 | AI15: =+'NOTAS ESF'!AE61 -> 13183193 | AJ15: =+'NOTAS ESF'!AF61 -> 13183193 | AK15: =+'NOTAS ESF'!AG61 -> 13183193 | AL15: =+'NOTAS ESF'!AH61 -> 13183193 | AM15: =+'NOTAS ESF'!AI61 -> 13183193 | AN15: =+'NOTAS ESF'!AJ61 -> 13183193 | AO15: =+'NOTAS ESF'!AK61 -> 13183193 | ... AS15: =+'NOTAS ESF'!AO61 -> 13183193 | AU15: =+'NOTAS ESF'!AQ61 -> 13183193 | AV15: =+'NOTAS ESF'!AR61 -> 9640732 | AW15: =+'NOTAS ESF'!AS61 -> 9853785 | AX15: =+'NOTAS ESF'!AT61 -> 10066838 | AY15: =+'NOTAS ESF'!AU61 -> 10279891 | AZ15: =+'NOTAS ESF'!AV61 -> 6892944 | BA15: =+'NOTAS ESF'!AW61 -> 7105997 | BB15: =+'NOTAS ESF'!AX61 -> 7319050 | ... BF15: =+'NOTAS ESF'!BB61 -> 8171262 | BH15: =+'NOTAS ESF'!BD61 -> 9583193 | BI15: =+'NOTAS ESF'!BE61 -> 0 | BJ15: =+'NOTAS ESF'!BF61 -> 0 | BK15: =+'NOTAS ESF'!BG61 -> 0 | BL15: =+'NOTAS ESF'!BH61 -> 0 | BM15: =+'NOTAS ESF'!BI61 -> 0 | BO15: =+'NOTAS ESF'!BK61 -> 0
B16: Activos Diferido | F16: =+'NOTAS ESF'!B69 -> 36327625 | H16: =+'NOTAS ESF'!D69 -> 36327625 | I16: =+'NOTAS ESF'!E69 -> 36327625 | J16: =+'NOTAS ESF'!F69 -> 36327625 | K16: =+'NOTAS ESF'!G69 -> 36327625 | L16: =+'NOTAS ESF'!H69 -> 36327625 | M16: =+'NOTAS ESF'!I69 -> 36327625 | N16: =+'NOTAS ESF'!J69 -> 36327625 | O16: =+'NOTAS ESF'!K69 -> 36327625 | ... S16: =+'NOTAS ESF'!O69 -> 36327625 | U16: =+'NOTAS ESF'!Q69 -> 36327625 | V16: =+'NOTAS ESF'!R69 -> 31808371 | W16: =+'NOTAS ESF'!S69 -> 29238600 | X16: =+'NOTAS ESF'!T69 -> 26656843 | Y16: =+'NOTAS ESF'!U69 -> 24207995 | Z16: =+'NOTAS ESF'!V69 -> 21747921 | AA16: =+'NOTAS ESF'!W69 -> 19339622 | AB16: =+'NOTAS ESF'!X69 -> 14232999 | ... AF16: =+'NOTAS ESF'!AB69 -> 2715692 | AH16: =+'NOTAS ESF'!AD69 -> 0 | AI16: =+'NOTAS ESF'!#REF! -> #REF! | AJ16: =+'NOTAS ESF'!#REF! -> #REF! | AK16: =+'NOTAS ESF'!#REF! -> #REF! | AL16: =+'NOTAS ESF'!#REF! -> #REF! | AM16: =+'NOTAS ESF'!#REF! -> #REF! | AN16: =+'NOTAS ESF'!#REF! -> #REF! | AO16: =+'NOTAS ESF'!#REF! -> #REF! | AP16: =+'NOTAS ESF'!#REF! -> #REF! | ... AS16: =+'NOTAS ESF'!#REF! -> #REF! | AU16: =+'NOTAS ESF'!AQ69 -> 24505488 | BH16: =+'NOTAS ESF'!BD69 -> 0 | BO16: =+'NOTAS ESF'!#REF! -> #REF!
B17: Total | F17: =SUM(F15:F16) -> 53714155 | H17: =SUM(H15:H16) -> 53714155 | I17: =SUM(I15:I16) -> 53714155 | J17: =SUM(J15:J16) -> 53714155 | K17: =SUM(K15:K16) -> 53714155 | L17: =SUM(L15:L16) -> 53714155 | M17: =SUM(M15:M16) -> 53714155 | N17: =SUM(N15:N16) -> 53714155 | O17: =SUM(O15:O16) -> 53714155 | ... S17: =SUM(S15:S16) -> 53714155 | U17: =SUM(U15:U16) -> 53714155 | V17: =SUM(V15:V16) -> 49194901 | W17: =SUM(W15:W16) -> 46625130 | X17: =SUM(X15:X16) -> 44043373 | Y17: =SUM(Y15:Y16) -> 41594525 | Z17: =SUM(Z15:Z16) -> 39134451 | AA17: =SUM(AA15:AA16) -> 36726152 | AB17: =SUM(AB15:AB16) -> 31619529 | ... AF17: =SUM(AF15:AF16) -> 20102222 | AH17: =SUM(AH15:AH16) -> 17386530 | AI17: =SUM(AI15:AI16) -> #REF! | AJ17: =SUM(AJ15:AJ16) -> #REF! | AK17: =SUM(AK15:AK16) -> #REF! | AL17: =SUM(AL15:AL16) -> #REF! | AM17: =SUM(AM15:AM16) -> #REF! | AN17: =SUM(AN15:AN16) -> #REF! | AO17: =SUM(AO15:AO16) -> #REF! | ... AS17: =SUM(AS15:AS16) -> #REF! | AU17: =SUM(AU15:AU16) -> 37688681 | AV17: =SUM(AV15:AV15) -> 9640732 | AW17: =SUM(AW15:AW15) -> 9853785 | AX17: =SUM(AX15:AX15) -> 10066838 | AY17: =SUM(AY15:AY15) -> 10279891 | AZ17: =SUM(AZ15:AZ15) -> 6892944 | BA17: =SUM(BA15:BA15) -> 7105997 | BB17: =SUM(BB15:BB15) -> 7319050 | BC17: =SUM(BC15:BC15) -> 7532103 | ... BF17: =SUM(BF15:BF15) -> 8171262 | BH17: =SUM(BH15:BH15) -> 9583193 | BI17: =SUM(BI15:BI15) -> 0 | BJ17: =SUM(BJ15:BJ15) -> 0 | BK17: =SUM(BK15:BK15) -> 0 | BL17: =SUM(BL15:BL15) -> 0 | BM17: =SUM(BM15:BM15) -> 0 | BO17: =SUM(BO15:BO15) -> 0
B19: Total Activo | F19: =+F12+F17 -> 1.4061731e+08 | H19: =+H12+H17 -> 1.458645e+08 | I19: =+I12+I17 -> 1.4665313e+08 | J19: =+J12+J17 -> 1.2134925e+08 | K19: =+K12+K17 -> 1.2162471e+08 | L19: =+L12+L17 -> 1.0368991e+08 | M19: =+M12+M17 -> 1.0129416e+08 | N19: =+N12+N17 -> 93443117 | O19: =+O12+O17 -> 1.0192369e+08 | ... S19: =+S12+S17 -> 69057330 | U19: =+U12+U17 -> 74355715 | V19: =+V12+V17 -> 68643331 | W19: =+W12+W17 -> 66495137 | X19: =+X12+X17 -> 71277754 | Y19: =+Y12+Y17 -> 65849265 | Z19: =+Z12+Z17 -> 62586229 | AA19: =+AA12+AA17 -> 57761111 | AB19: =+AB12+AB17 -> 63488667 | ... AF19: =+AF12+AF17 -> 48427369 | AH19: =+AH12+AH17 -> 40074048 | AI19: =+AI12+AI17 -> #REF! | AJ19: =+AJ12+AJ17 -> #REF! | AK19: =+AK12+AK17 -> #REF! | AL19: =+AL12+AL17 -> #REF! | AM19: =+AM12+AM17 -> #REF! | AN19: =+AN12+AN17 -> #REF! | AO19: =+AO12+AO17 -> #REF! | ... AS19: =+AS12+AS17 -> #REF! | AU19: =+AU12+AU17 -> 44054429 | AV19: =+AV17+AV12 -> 10528394 | AW19: =+AW17+AW12 -> 49996276 | AX19: =+AX17+AX12 -> 64151629 | AY19: =+AY17+AY12 -> 41459709 | AZ19: =+AZ17+AZ12 -> 24099033 | BA19: =+BA17+BA12 -> 24312086 | BB19: =+BB17+BB12 -> 24525139 | BC19: =+BC17+BC12 -> 25338364 | ... BF19: =+BF17+BF12 -> 19857850 | BH19: =+BH17+BH12 -> 25306581 | BI19: =+BI17+BI12 -> 0 | BJ19: =+BJ17+BJ12 -> 0 | BK19: =+BK17+BK12 -> 0 | BL19: =+BL17+BL12 -> 0 | BM19: =+BM17+BM12 -> 0 | BO19: =+BO17+BO12 -> 2000000
B21: PASIVOS
B23: Corriente
B24: Financieros | D24: 8 | F24: 0 | H24: 0 | I24: 0 | J24: 0 | K24: 0 | L24: 0 | M24: 0 | N24: 0 | O24: 0 | P24: 0 | Q24: 0 | R24: 0 | S24: 0 | U24: 0 | AX24: =+'NOTAS ESF'!#REF!*20% -> #REF! | AY24: =+'NOTAS ESF'!#REF!*20% -> #REF! | AZ24: =+'NOTAS ESF'!#REF!*20% -> #REF! | BA24: =+'NOTAS ESF'!#REF!*20% -> #REF! | BB24: =+'NOTAS ESF'!#REF!*20% -> #REF! | BC24: =+'NOTAS ESF'!#REF!*20% -> #REF! | BD24: =+'NOTAS ESF'!#REF!*20% -> #REF! | BE24: =+'NOTAS ESF'!#REF!*20% -> #REF! | BF24: =+'NOTAS ESF'!#REF!*20% -> #REF! | BH24: 0 | BI24: =+'NOTAS ESF'!#REF!*20% -> #REF! | BJ24: =+'NOTAS ESF'!#REF!*20% -> #REF! | BK24: =+'NOTAS ESF'!#REF!*20% -> #REF! | BL24: =+'NOTAS ESF'!#REF!*20% -> #REF! | BM24: =+'NOTAS ESF'!#REF!*20% -> #REF! | BO24: =+'NOTAS ESF'!#REF!*20% -> #REF!
B25: Proveedores Y Acreedores Comerciales | D25: 7 | F25: 0 | H25: 0 | I25: 0 | J25: 0 | K25: 0 | L25: 0 | M25: 0 | N25: 0 | O25: 0 | P25: 0 | Q25: 0 | R25: 0 | S25: 0 | U25: 0 | V25: 0 | W25: 0 | X25: 0 | Y25: 0 | Z25: 0 | AA25: 0 | AB25: 0 | AC25: 0 | AD25: 0 | AE25: 0 | AF25: 0 | AH25: 0 | AI25: 0 | AJ25: 0 | AK25: 0 | AL25: 0 | AM25: 0 | AN25: 0 | AO25: 0 | AP25: 0 | AQ25: 0 | AR25: 0 | AS25: 0 | AU25: 0 | AV25: 0 | AW25: 0 | AX25: 0 | AY25: 0 | AZ25: 0 | BA25: 0 | BB25: 0 | BC25: 0 | BD25: 0 | BE25: 0 | BF25: 0 | BH25: 0 | BI25: =+'NOTAS ESF'!#REF! -> #REF! | BJ25: =+'NOTAS ESF'!#REF! -> #REF! | BK25: =+'NOTAS ESF'!#REF! -> #REF! | BL25: =+'NOTAS ESF'!#REF! -> #REF! | BM25: =+'NOTAS ESF'!#REF! -> #REF! | BO25: 0
B26: Costos y Gastos Por Pagar | D26: 7 | F26: =+'NOTAS ESF'!B79 -> 4558817 | H26: =+'NOTAS ESF'!D79 -> 10155997 | I26: =+'NOTAS ESF'!E79 -> 9427003 | J26: =+'NOTAS ESF'!F79 -> 13568568 | K26: =+'NOTAS ESF'!G79 -> 13337057 | L26: =+'NOTAS ESF'!H79 -> 16305931 | M26: =+'NOTAS ESF'!I79 -> 19749101 | N26: =+'NOTAS ESF'!J79 -> 17140322 | O26: =+'NOTAS ESF'!K79 -> 20848428 | ... S26: =+'NOTAS ESF'!O79 -> 7877156 | U26: =+'NOTAS ESF'!Q79 -> 6941830 | V26: =+'NOTAS ESF'!R79 -> 2593000 | W26: =+'NOTAS ESF'!S79 -> 3691704 | X26: =+'NOTAS ESF'!T79 -> 4055497 | Y26: =+'NOTAS ESF'!U79 -> 2763553 | Z26: =+'NOTAS ESF'!V79 -> 2996811 | AA26: =+'NOTAS ESF'!W79 -> 2161391 | AB26: =+'NOTAS ESF'!X79 -> 3213352 | ... AF26: =+'NOTAS ESF'!AB79 -> 1329009 | BI26: =+'NOTAS ESF'!#REF!*20% -> #REF! | BJ26: =+'NOTAS ESF'!#REF!*20% -> #REF! | BK26: =+'NOTAS ESF'!#REF!*20% -> #REF! | BL26: =+'NOTAS ESF'!#REF!*20% -> #REF! | BM26: =+'NOTAS ESF'!#REF!*20% -> #REF! | BO26: 0
B27: No Finaniceros | D27: 8 | F27: =+'NOTAS ESF'!B98 -> 4356900 | H27: =+'NOTAS ESF'!D98 -> 3776000 | I27: =+'NOTAS ESF'!E98 -> 3856900 | J27: =+'NOTAS ESF'!F98 -> 3856900 | K27: =+'NOTAS ESF'!G98 -> 3808700 | L27: =+'NOTAS ESF'!H98 -> 3838500 | M27: =+'NOTAS ESF'!I98 -> 3856900 | N27: =+'NOTAS ESF'!J98 -> 3769500 | O27: =+'NOTAS ESF'!K98 -> 3669800 | ... S27: =+'NOTAS ESF'!O98 -> 698600 | U27: =+'NOTAS ESF'!Q98 -> 637600 | V27: =+'NOTAS ESF'!R98 -> 637600 | W27: =+'NOTAS ESF'!S98 -> 1636800 | X27: =+'NOTAS ESF'!T98 -> 1912800 | Y27: =+'NOTAS ESF'!U98 -> 1912800 | Z27: =+'NOTAS ESF'!V98 -> 1923700 | AA27: =+'NOTAS ESF'!W98 -> 2242500 | AB27: =+'NOTAS ESF'!X98 -> 3188000 | ... AF27: =+'NOTAS ESF'!AB98 -> 956400 | AH27: =+'NOTAS ESF'!AD98 -> 897900 | AI27: =+'NOTAS ESF'!AE98 -> 897900 | AJ27: =+'NOTAS ESF'!AF98 -> 1719000 | AK27: =+'NOTAS ESF'!AG98 -> 809400 | AL27: =+'NOTAS ESF'!AH98 -> 875700 | AM27: =+'NOTAS ESF'!AI98 -> 569000 | AN27: =+'NOTAS ESF'!AJ98 -> 720794 | AO27: =+'NOTAS ESF'!AK98 -> 569000 | ... AS27: =+'NOTAS ESF'!AO98 -> 569000 | AU27: =+'NOTAS ESF'!AQ98 -> 780400 | AV27: =+'NOTAS ESF'!AR98 -> 1492900 | AW27: =+'NOTAS ESF'!AS98 -> 1098944 | AX27: =+'NOTAS ESF'!AT98 -> 391956 | AY27: =+'NOTAS ESF'!AU98 -> 363278 | AZ27: =+'NOTAS ESF'!AV98 -> 513452 | BA27: =+'NOTAS ESF'!AW98 -> 374078 | BB27: =+'NOTAS ESF'!AX98 -> 374078 | ... BF27: =+'NOTAS ESF'!BB98 -> 116522 | BH27: =+'NOTAS ESF'!BD98 -> 446000 | BI27: =+'NOTAS ESF'!BE98 -> 0 | BJ27: =+'NOTAS ESF'!BF98 -> 0 | BK27: =+'NOTAS ESF'!BG98 -> 0 | BL27: =+'NOTAS ESF'!BH98 -> 0 | BM27: =+'NOTAS ESF'!BI98 -> 0 | BO27: =+'NOTAS ESF'!BK98 -> 0
B28: Fiscales | D28: 9 | F28: =+'NOTAS ESF'!B107 -> 38753449 | H28: =+'NOTAS ESF'!D107 -> 40687062 | I28: =+'NOTAS ESF'!E107 -> 36865926 | J28: =+'NOTAS ESF'!F107 -> 32224889 | K28: =+'NOTAS ESF'!G107 -> 27343774 | L28: =+'NOTAS ESF'!H107 -> 20796788 | M28: =+'NOTAS ESF'!I107 -> 21537467 | N28: =+'NOTAS ESF'!J107 -> 23015077 | O28: =+'NOTAS ESF'!K107 -> 24848147 | ... S28: =+'NOTAS ESF'!O107 -> 30697551 | U28: =+'NOTAS ESF'!Q107 -> 32974361 | V28: =+'NOTAS ESF'!R107 -> 32800049 | W28: =+'NOTAS ESF'!S107 -> 30758162 | X28: =+'NOTAS ESF'!T107 -> 31769128 | Y28: =+'NOTAS ESF'!U107 -> 31003445 | Z28: =+'NOTAS ESF'!V107 -> 29069622 | AA28: =+'NOTAS ESF'!W107 -> 26373928 | AB28: =+'NOTAS ESF'!X107 -> 27514427 | ... AF28: =+'NOTAS ESF'!AB107 -> 24251628 | AH28: =+'NOTAS ESF'!AD107 -> 19565238 | AI28: =+'NOTAS ESF'!AE107 -> 14531905 | AJ28: =+'NOTAS ESF'!AF107 -> 13621990 | AK28: =+'NOTAS ESF'!AG107 -> 11593683 | AL28: =+'NOTAS ESF'!AH107 -> 10977523 | AM28: =+'NOTAS ESF'!AI107 -> 10012082 | AN28: =+'NOTAS ESF'!AJ107 -> 9171171.7 | AO28: =+'NOTAS ESF'!AK107 -> 8670615.1 | ... AS28: =+'NOTAS ESF'!AO107 -> 268308 | AU28: =+'NOTAS ESF'!AQ107 -> 4036561 | AV28: =+'NOTAS ESF'!AR107 -> 3427601 | AW28: =+'NOTAS ESF'!AS107 -> 3427601 | AX28: =+'NOTAS ESF'!AT107 -> 2823278.4 | AY28: =+'NOTAS ESF'!AU107 -> 1827340.1 | AZ28: =+'NOTAS ESF'!AV107 -> -25516.32 | BA28: =+'NOTAS ESF'!AW107 -> 27081.76 | BB28: =+'NOTAS ESF'!AX107 -> 93272.21 | ... BF28: =+'NOTAS ESF'!BB107 -> -648977.02 | BH28: =+'NOTAS ESF'!BD107 -> 294499.83 | BI28: =+'NOTAS ESF'!BE107 -> 0 | BJ28: =+'NOTAS ESF'!BF107 -> 0 | BK28: =+'NOTAS ESF'!BG107 -> 0 | BL28: =+'NOTAS ESF'!BH107 -> 0 | BM28: =+'NOTAS ESF'!BI107 -> 0 | BO28: =+'NOTAS ESF'!BK107 -> 0
B29: Por Beneficios a Empleados | D29: 10 | F29: =+'NOTAS ESF'!B118 -> 44679735 | H29: =+'NOTAS ESF'!D118 -> 35230529 | I29: =+'NOTAS ESF'!E118 -> 46596939 | J29: =+'NOTAS ESF'!F118 -> 29319455 | K29: =+'NOTAS ESF'!G118 -> 44412470 | L29: =+'NOTAS ESF'!H118 -> 40577188 | M29: =+'NOTAS ESF'!I118 -> 36741704 | N29: =+'NOTAS ESF'!J118 -> 33292159 | O29: =+'NOTAS ESF'!K118 -> 37217535 | ... S29: =+'NOTAS ESF'!O118 -> 16395504 | U29: =+'NOTAS ESF'!Q118 -> 16398640 | V29: =+'NOTAS ESF'!R118 -> 16775928 | W29: =+'NOTAS ESF'!S118 -> 16355689 | X29: =+'NOTAS ESF'!T118 -> 20855057 | Y29: =+'NOTAS ESF'!U118 -> 17768027 | Z29: =+'NOTAS ESF'!V118 -> 17113268 | AA29: =+'NOTAS ESF'!W118 -> 17254521 | AB29: =+'NOTAS ESF'!X118 -> 17747629 | ... AF29: =+'NOTAS ESF'!AB118 -> 11572647 | AH29: =+'NOTAS ESF'!AD118 -> 10384219 | AI29: =+'NOTAS ESF'!AE118 -> 11172268 | AJ29: =+'NOTAS ESF'!AF118 -> 10466235 | AK29: =+'NOTAS ESF'!AG118 -> 5838235 | AL29: =+'NOTAS ESF'!AH118 -> 5506749 | AM29: =+'NOTAS ESF'!AI118 -> 4822615 | AN29: =+'NOTAS ESF'!AJ118 -> 5416539 | AO29: =+'NOTAS ESF'!AK118 -> 5076869 | ... AS29: =+'NOTAS ESF'!AO118 -> 3714002 | AU29: =+'NOTAS ESF'!AQ118 -> 3419676.7 | AV29: =+'NOTAS ESF'!AR118 -> 6199779 | AW29: =+'NOTAS ESF'!AS118 -> 5368633 | AX29: =+'NOTAS ESF'!AT118 -> 4087491 | AY29: =+'NOTAS ESF'!AU118 -> 2824195 | AZ29: =+'NOTAS ESF'!AV118 -> 2579874 | BA29: =+'NOTAS ESF'!AW118 -> 2162737 | BB29: =+'NOTAS ESF'!AX118 -> 2463015 | ... BF29: =+'NOTAS ESF'!BB118 -> 2415217 | BH29: =+'NOTAS ESF'!BD118 -> 1499566.3 | BI29: =+'NOTAS ESF'!BE118 -> 0 | BJ29: =+'NOTAS ESF'!BF118 -> 0 | BK29: =+'NOTAS ESF'!BG118 -> 0 | BL29: =+'NOTAS ESF'!BH118 -> 0 | BM29: =+'NOTAS ESF'!BI118 -> 0 | BO29: =+'NOTAS ESF'!BK118 -> 0
B30: Total | F30: =SUM(F24:F29) -> 92348901 | H30: =SUM(H24:H29) -> 89849588 | I30: =SUM(I24:I29) -> 96746768 | J30: =SUM(J24:J29) -> 78969812 | K30: =SUM(K24:K29) -> 88902001 | L30: =SUM(L24:L29) -> 81518407 | M30: =SUM(M24:M29) -> 81885172 | N30: =SUM(N24:N29) -> 77217058 | O30: =SUM(O24:O29) -> 86583910 | ... S30: =SUM(S24:S29) -> 55668811 | U30: =SUM(U24:U29) -> 56952431 | V30: =SUM(V24:V29) -> 52806577 | W30: =SUM(W24:W29) -> 52442355 | X30: =SUM(X24:X29) -> 58592482 | Y30: =SUM(Y24:Y29) -> 53447825 | Z30: =SUM(Z24:Z29) -> 51103401 | AA30: =SUM(AA24:AA29) -> 48032340 | AB30: =SUM(AB24:AB29) -> 51663408 | ... AF30: =SUM(AF24:AF29) -> 38109684 | AH30: =SUM(AH24:AH29) -> 30847357 | AI30: =SUM(AI24:AI29) -> 26602073 | AJ30: =SUM(AJ24:AJ29) -> 25807225 | AK30: =SUM(AK24:AK29) -> 18241318 | AL30: =SUM(AL24:AL29) -> 17359972 | AM30: =SUM(AM24:AM29) -> 15403697 | AN30: =SUM(AN24:AN29) -> 15308505 | AO30: =SUM(AO24:AO29) -> 14316484 | ... AS30: =SUM(AS24:AS29) -> 4551310 | AU30: =SUM(AU24:AU29) -> 8236637.7 | AV30: =SUM(AV24:AV29) -> 11120280 | AW30: =SUM(AW24:AW29) -> 9895178 | AX30: =+AX27+AX28+AX29 -> 7302725.4 | AY30: =+AY27+AY28+AY29 -> 5014813.1 | AZ30: =+AZ27+AZ28+AZ29 -> 3067809.7 | BA30: =+BA27+BA28+BA29 -> 2563896.8 | BB30: =+BB27+BB28+BB29 -> 2930365.2 | BC30: =+BC27+BC28+BC29 -> 2899502.2 | BD30: =+BD27+BD28+BD29 -> 2646652.7 | BE30: =+BE27+BE28+BE29 -> 1281004.5 | BF30: =+BF27+BF28+BF29 -> 1882762 | BH30: =SUM(BH24:BH29) -> 2240066.2 | BI30: =SUM(BI24:BI29) -> #REF! | BJ30: =SUM(BJ24:BJ29) -> #REF! | BK30: =SUM(BK24:BK29) -> #REF! | BL30: =SUM(BL24:BL29) -> #REF! | BM30: =SUM(BM24:BM29) -> #REF! | BO30: =SUM(BO24:BO29) -> #REF!
B32: No corriente
B33: Consignaciones sin Identificar | D33: 11 | F33: =+'NOTAS ESF'!B125 -> 6684000 | H33: =+'NOTAS ESF'!D125 -> 6684000 | I33: =+'NOTAS ESF'!E125 -> 6684000 | J33: =+'NOTAS ESF'!F125 -> 6684000 | K33: =+'NOTAS ESF'!G125 -> 6684000 | L33: =+'NOTAS ESF'!H125 -> 6684000 | M33: =+'NOTAS ESF'!I125 -> 6684000 | N33: =+'NOTAS ESF'!J125 -> 4284000 | O33: =+'NOTAS ESF'!K125 -> 4284000 | ... S33: =+'NOTAS ESF'!O125 -> 0 | U33: =+'NOTAS ESF'!Q125 -> 0 | V33: =+'NOTAS ESF'!R125 -> 0 | W33: =+'NOTAS ESF'!S125 -> 0 | X33: =+'NOTAS ESF'!T125 -> 0 | Y33: =+'NOTAS ESF'!U125 -> 0 | Z33: =+'NOTAS ESF'!V125 -> 0 | AA33: =+'NOTAS ESF'!W125 -> 0 | AB33: =+'NOTAS ESF'!X125 -> 1685431 | ... AF33: =+'NOTAS ESF'!AB125 -> 0 | AH33: =+'NOTAS ESF'!AD79 -> 40000 | AI33: =+'NOTAS ESF'!AE79 -> 29910000 | AJ33: =+'NOTAS ESF'!AF79 -> 33910000 | AK33: =+'NOTAS ESF'!AG79 -> 29910000 | AL33: =+'NOTAS ESF'!AH79 -> 34210385 | AM33: =+'NOTAS ESF'!AI79 -> 36724324 | AN33: =+'NOTAS ESF'!AJ79 -> 75507001 | AO33: =+'NOTAS ESF'!AK79 -> 71511775 | ... AS33: =+'NOTAS ESF'!AO79 -> 35845172 | AU33: =+'NOTAS ESF'!AQ79 -> 32460000 | AV33: =+'NOTAS ESF'!AR79 -> 1694936.5 | AW33: =+'NOTAS ESF'!AS79 -> 42400371 | AX33: =+'NOTAS ESF'!AT79 -> 43938473 | AY33: =+'NOTAS ESF'!AU79 -> 27215890 | AZ33: =+'NOTAS ESF'!AV79 -> 18825168 | BA33: =+'NOTAS ESF'!AW79 -> 18846889 | BB33: =+'NOTAS ESF'!AX79 -> 18760643 | ... BF33: =+'NOTAS ESF'!BB79 -> 17136601 | BH33: =+'NOTAS ESF'!BD79 -> 20000000 | BI33: =+'NOTAS ESF'!#REF!*80% -> #REF! | BJ33: =+'NOTAS ESF'!#REF!*80% -> #REF! | BK33: =+'NOTAS ESF'!#REF!*80% -> #REF! | BL33: =+'NOTAS ESF'!#REF!*80% -> #REF! | BM33: =+'NOTAS ESF'!#REF!*80% -> #REF! | BO33: =+'NOTAS ESF'!#REF!*80% -> #REF!
B34: Total | F34: =SUM(F32:F33) -> 6684000 | H34: =SUM(H32:H33) -> 6684000 | I34: =SUM(I32:I33) -> 6684000 | J34: =SUM(J32:J33) -> 6684000 | K34: =SUM(K32:K33) -> 6684000 | L34: =SUM(L32:L33) -> 6684000 | M34: =SUM(M32:M33) -> 6684000 | N34: =SUM(N32:N33) -> 4284000 | O34: =SUM(O32:O33) -> 4284000 | ... S34: =SUM(S32:S33) -> 0 | U34: =SUM(U32:U33) -> 0 | V34: =SUM(V32:V33) -> 0 | W34: =SUM(W32:W33) -> 0 | X34: =SUM(X32:X33) -> 0 | Y34: =SUM(Y32:Y33) -> 0 | Z34: =SUM(Z32:Z33) -> 0 | AA34: =SUM(AA32:AA33) -> 0 | AB34: =SUM(AB32:AB33) -> 1685431 | ... AF34: =SUM(AF32:AF33) -> 0 | AH34: =SUM(AH32:AH33) -> 40000 | AI34: =SUM(AI32:AI33) -> 29910000 | AJ34: =SUM(AJ32:AJ33) -> 33910000 | AK34: =SUM(AK32:AK33) -> 29910000 | AL34: =SUM(AL32:AL33) -> 34210385 | AM34: =SUM(AM32:AM33) -> 36724324 | AN34: =SUM(AN32:AN33) -> 75507001 | AO34: =SUM(AO32:AO33) -> 71511775 | ... AS34: =SUM(AS32:AS33) -> 35845172 | AU34: =SUM(AU32:AU33) -> 32460000 | AV34: =SUM(AV32:AV33) -> 1694936.5 | AW34: =SUM(AW32:AW33) -> 42400371 | AX34: =SUM(AX32:AX33) -> 43938473 | AY34: =SUM(AY32:AY33) -> 27215890 | AZ34: =SUM(AZ32:AZ33) -> 18825168 | BA34: =SUM(BA32:BA33) -> 18846889 | BB34: =SUM(BB32:BB33) -> 18760643 | ... BF34: =SUM(BF32:BF33) -> 17136601 | BH34: =SUM(BH32:BH33) -> 20000000 | BI34: =SUM(BI32:BI33) -> #REF! | BJ34: =SUM(BJ32:BJ33) -> #REF! | BK34: =SUM(BK32:BK33) -> #REF! | BL34: =SUM(BL32:BL33) -> #REF! | BM34: =SUM(BM32:BM33) -> #REF! | BO34: =SUM(BO32:BO33) -> #REF!
B36: Total Pasivo | F36: =+F34+F30 -> 99032901 | H36: =+H34+H30 -> 96533588 | I36: =+I34+I30 -> 1.0343077e+08 | J36: =+J34+J30 -> 85653812 | K36: =+K34+K30 -> 95586001 | L36: =+L34+L30 -> 88202407 | M36: =+M34+M30 -> 88569172 | N36: =+N34+N30 -> 81501058 | O36: =+O34+O30 -> 90867910 | ... S36: =+S34+S30 -> 55668811 | U36: =+U34+U30 -> 56952431 | V36: =+V34+V30 -> 52806577 | W36: =+W34+W30 -> 52442355 | X36: =+X34+X30 -> 58592482 | Y36: =+Y34+Y30 -> 53447825 | Z36: =+Z34+Z30 -> 51103401 | AA36: =+AA34+AA30 -> 48032340 | AB36: =+AB34+AB30 -> 53348839 | ... AF36: =+AF34+AF30 -> 38109684 | AH36: =+AH34+AH30 -> 30887357 | AI36: =+AI34+AI30 -> 56512073 | AJ36: =+AJ34+AJ30 -> 59717225 | AK36: =+AK34+AK30 -> 48151318 | AL36: =+AL34+AL30 -> 51570357 | AM36: =+AM34+AM30 -> 52128021 | AN36: =+AN34+AN30 -> 90815506 | AO36: =+AO34+AO30 -> 85828259 | ... AS36: =+AS34+AS30 -> 40396482 | AU36: =+AU34+AU30 -> 40696638 | AV36: =+AV34+AV30 -> 12815216 | AW36: =+AW34+AW30 -> 52295549 | AX36: =+AX34+AX30 -> 51241198 | AY36: =+AY34+AY30 -> 32230703 | AZ36: =+AZ34+AZ30 -> 21892978 | BA36: =+BA34+BA30 -> 21410786 | BB36: =+BB34+BB30 -> 21691009 | ... BF36: =+BF34+BF30 -> 19019363 | BH36: =+BH34+BH30 -> 22240066 | BI36: =+BI34+BI30 -> #REF! | BJ36: =+BJ34+BJ30 -> #REF! | BK36: =+BK34+BK30 -> #REF! | BL36: =+BL34+BL30 -> #REF! | BM36: =+BM34+BM30 -> #REF! | BO36: =+BO34+BO30 -> #REF!
B38: PATRIMONIO
B40: Capital Social | D40: 12 | F40: =+'NOTAS ESF'!B131 -> 2000000 | H40: =+'NOTAS ESF'!D131 -> 2000000 | I40: =+'NOTAS ESF'!E131 -> 2000000 | J40: =+'NOTAS ESF'!F131 -> 2000000 | K40: =+'NOTAS ESF'!G131 -> 2000000 | L40: =+'NOTAS ESF'!H131 -> 2000000 | M40: =+'NOTAS ESF'!I131 -> 2000000 | N40: =+'NOTAS ESF'!J131 -> 2000000 | O40: =+'NOTAS ESF'!K131 -> 2000000 | ... S40: =+'NOTAS ESF'!O131 -> 2000000 | U40: =+'NOTAS ESF'!Q131 -> 2000000 | V40: =+'NOTAS ESF'!R131 -> 2000000 | W40: =+'NOTAS ESF'!S131 -> 2000000 | X40: =+'NOTAS ESF'!T131 -> 2000000 | Y40: =+'NOTAS ESF'!U131 -> 2000000 | Z40: =+'NOTAS ESF'!V131 -> 2000000 | AA40: =+'NOTAS ESF'!W131 -> 2000000 | AB40: =+'NOTAS ESF'!X131 -> 2000000 | ... AF40: =+'NOTAS ESF'!AB131 -> 2000000 | AH40: =+'NOTAS ESF'!AD131 -> 2000000 | AI40: =+'NOTAS ESF'!AE131 -> 2000000 | AJ40: =+'NOTAS ESF'!AF131 -> 2000000 | AK40: =+'NOTAS ESF'!AG131 -> 2000000 | AL40: =+'NOTAS ESF'!AH131 -> 2000000 | AM40: =+'NOTAS ESF'!AI131 -> 2000000 | AN40: =+'NOTAS ESF'!AJ131 -> 2000000 | AO40: =+'NOTAS ESF'!AK131 -> 2000000 | ... AS40: =+'NOTAS ESF'!AO131 -> 2000000 | AU40: =+'NOTAS ESF'!AQ131 -> 2000000 | AV40: =+'NOTAS ESF'!AR131 -> 2000000 | AW40: =+'NOTAS ESF'!AS131 -> 2000000 | AX40: =+'NOTAS ESF'!AT131 -> 2000000 | AY40: =+'NOTAS ESF'!AU131 -> 2000000 | AZ40: =+'NOTAS ESF'!AV131 -> 2000000 | BA40: =+'NOTAS ESF'!AW131 -> 2000000 | BB40: =+'NOTAS ESF'!AX131 -> 2000000 | ... BF40: =+'NOTAS ESF'!BB131 -> 2000000 | BH40: =+'NOTAS ESF'!BD131 -> 2000000 | BI40: =+'NOTAS ESF'!BE131 -> 0 | BJ40: =+'NOTAS ESF'!BF131 -> 0 | BK40: =+'NOTAS ESF'!BG131 -> 0 | BL40: =+'NOTAS ESF'!BH131 -> 0 | BM40: =+'NOTAS ESF'!BI131 -> 0 | BO40: =+'NOTAS ESF'!BK131 -> 2000000
B41: Capital suscrito y Pagado
B42: Reservas | D42: 13 | F42: =+'NOTAS ESF'!B133 -> 129048 | H42: =+'NOTAS ESF'!D133 -> 129048 | I42: =+'NOTAS ESF'!E133 -> 129048 | J42: =+'NOTAS ESF'!F133 -> 129048 | K42: =+'NOTAS ESF'!G133 -> 129048 | L42: =+'NOTAS ESF'!H133 -> 129048 | M42: =+'NOTAS ESF'!I133 -> 129048 | N42: =+'NOTAS ESF'!J133 -> 129048 | O42: =+'NOTAS ESF'!K133 -> 129048 | ... S42: =+'NOTAS ESF'!O133 -> 129048 | U42: =+'NOTAS ESF'!Q133 -> 129048 | V42: =+'NOTAS ESF'!R133 -> 129048 | W42: =+'NOTAS ESF'!S133 -> 129048 | X42: =+'NOTAS ESF'!T133 -> 129048 | Y42: =+'NOTAS ESF'!U133 -> 129048 | Z42: =+'NOTAS ESF'!V133 -> 129048 | AA42: =+'NOTAS ESF'!W133 -> 129048 | AB42: =+'NOTAS ESF'!X133 -> 129048 | ... AF42: =+'NOTAS ESF'!AB133 -> 129048 | AH42: 129048 | AI42: =+'NOTAS ESF'!AE133 -> 117317 | AJ42: =+'NOTAS ESF'!AF133 -> 117317 | AK42: =+'NOTAS ESF'!AG133 -> 117317 | AL42: =+'NOTAS ESF'!AH133 -> 117317 | AM42: =+'NOTAS ESF'!AI133 -> 117317 | AN42: =+'NOTAS ESF'!AJ133 -> 117317 | AO42: =+'NOTAS ESF'!AK133 -> 117317 | AP42: =+'NOTAS ESF'!AL133 -> 117317 | ... AS42: =+'NOTAS ESF'!AO133 -> 117317 | AU42: =+'NOTAS ESF'!AQ133 -> 106651.5 | AV42: =+'NOTAS ESF'!AR133 -> 106651.5 | AW42: =+'NOTAS ESF'!AS133 -> 106651.5 | AX42: =+'NOTAS ESF'!AT133 -> 106651.5 | AY42: =+'NOTAS ESF'!AU133 -> 106651.5 | AZ42: =+'NOTAS ESF'!AV133 -> 106651.5 | BA42: =+'NOTAS ESF'!AW133 -> 106651.5 | BB42: =+'NOTAS ESF'!AX133 -> 106651.5 | ... BF42: =+'NOTAS ESF'!BB133 -> 0 | BH42: =+'NOTAS ESF'!BD133 -> 0 | BI42: =+'NOTAS ESF'!BE133 -> 0 | BJ42: =+'NOTAS ESF'!BF133 -> 0 | BK42: =+'NOTAS ESF'!BG133 -> 0 | BL42: =+'NOTAS ESF'!BH133 -> 0 | BM42: =+'NOTAS ESF'!BI133 -> 0 | BO42: =+'NOTAS ESF'!BK133 -> 0
B43: Donaciones en Bienes inmuebles
B44: Resultado de ejercicios anteriores | D44: 12 | F44: =+H44+H45 -> 47201868 | H44: =+I44 -> 15274236 | I44: =+J44 -> 15274236 | J44: =+K44 -> 15274236 | K44: =+L44 -> 15274236 | L44: =+M44 -> 15274236 | M44: =+N44 -> 15274236 | N44: =+O44 -> 15274236 | O44: =+P44 -> 15274236 | ... R44: =+S44 -> 15274236 | S44: =+U44+U45 -> 15274236 | U44: =+'NOTAS ESF'!Q135 -> 7057643.6 | V44: =+'NOTAS ESF'!R135 -> 7057643.6 | W44: =+'NOTAS ESF'!S135 -> 7057643.6 | X44: =+'NOTAS ESF'!T135 -> 7057643.6 | Y44: =+'NOTAS ESF'!U135 -> 7057643.6 | Z44: =+'NOTAS ESF'!V135 -> 7057643.6 | AA44: =+'NOTAS ESF'!W135 -> 7057643.6 | AB44: =+AC44 -> 7057643.6 | AC44: =+AD44 -> 7057643.6 | AD44: =+AE44 -> 7057643.6 | AE44: =+AF44 -> 7057643.6 | AF44: =+AH44+AH45 -> 7057643.6 | AH44: =+AU45+AU42+AU44-AH42 -> 1228743.5 | AI44: =+'NOTAS ESF'!AE135 -> 1114604.8 | AJ44: =+'NOTAS ESF'!AF135 -> 1114604.8 | AK44: =+'NOTAS ESF'!AG135 -> 1114604.8 | AL44: =+'NOTAS ESF'!AH135 -> 1114604.8 | AM44: =+'NOTAS ESF'!AI135 -> 1114604.8 | AN44: =+'NOTAS ESF'!AJ135 -> 1240474.5 | AO44: =+'NOTAS ESF'!AK135 -> 1240474.5 | AP44: =+'NOTAS ESF'!AL135 -> 1240474.5 | ... AS44: =+'NOTAS ESF'!AO135 -> 1240474.5 | AU44: =+'NOTAS ESF'!AQ135 -> 960703.5 | AV44: =+'NOTAS ESF'!AR135 -> 960703.5 | AW44: =+'NOTAS ESF'!AS135 -> 960703.5 | AX44: =+'NOTAS ESF'!AT135 -> 960703.5 | AY44: =+'NOTAS ESF'!AU135 -> 960703.5 | AZ44: =+'NOTAS ESF'!AV135 -> 960703.5 | BA44: =+'NOTAS ESF'!AW135 -> 960703.5 | BB44: =+'NOTAS ESF'!AX135 -> 960703.5 | ... BF44: =+'NOTAS ESF'!BB135 -> 1066515 | BH44: =+'NOTAS ESF'!BD135 -> 0 | BI44: =+'NOTAS ESF'!BE135 -> 0 | BJ44: =+'NOTAS ESF'!BF135 -> 0 | BK44: =+'NOTAS ESF'!BG135 -> 0 | BL44: =+'NOTAS ESF'!BH135 -> 0 | BM44: =+'NOTAS ESF'!BI135 -> 0 | BO44: =+'NOTAS ESF'!BK135 -> 0
B45: Resultado del ejercicio | D45: 12 | F45: =+ERI!Q51 -> -7746505 | H45: =+ERI!T51+I45 -> 31927632 | I45: =+ERI!U51+J45 -> 25819078 | J45: =+ERI!V51+K45 -> 18292156 | K45: =+ERI!W51+L45 -> 8635424.8 | L45: =+ERI!X51+M45 -> -1915776.3 | M45: =+ERI!Y51+N45 -> -4678299.4 | N45: =+ERI!Z51+O45 -> -5461225.1 | O45: =+ERI!AA51+P45 -> -6347508.5 | ... R45: =+ERI!AD51+S45 -> -7076854.4 | S45: =+ERI!AE51 -> -4014765.5 | U45: =+V45+ERI!AH51 -> 8216592.3 | V45: =+W45+ERI!AI51 -> 6650062.4 | W45: =+X45+ERI!AJ51 -> 4866090.6 | X45: =+ERI!AK51+ERI!AL51+ERI!AM51+ERI!AN51+ERI!AO51+ERI!AP51+ERI!AQ51+ERI!AR51+ERI!AS51 -> 3498580.3 | Y45: =+ERI!AS51+ERI!AR51+ERI!AQ51+ERI!AP51+ERI!AO51+ERI!AN51+ERI!AM51+ERI!AL51 -> 3214748 | Z45: =+ERI!AS51+ERI!AR51+ERI!AQ51+ERI!AP51+ERI!AO51+ERI!AN51+ERI!AM51 -> 2296135.5 | AA45: =+ERI!AS51+ERI!AR51+ERI!AQ51+ERI!AP51+ERI!AO51+ERI!AN51 -> 542079.42 | AB45: =+ERI!AS51+ERI!AR51+ERI!AQ51+ERI!AP51+ERI!AO51 -> 953136.17 | AC45: =+AD45+ERI!AP51 -> 153512.45 | AD45: =+ERI!AS51+ERI!AR51+ERI!AQ51 -> 1460856.1 | AE45: =+ERI!AS51+ERI!AR51 -> 459221.75 | AF45: =+ERI!AS51 -> 1130992.9 | AH45: =+ERI!AU51 -> 5828900.1 | AI45: =+AJ45+ERI!AW51 -> 9929259.6 | AJ45: =+AK45+ERI!AX51 -> 8668729.7 | AK45: =+AL45+ERI!AY51 -> 3595128.7 | AL45: =+AM45+ERI!AZ51 -> 7061106.7 | AM45: =+AN45+ERI!BA51 -> 8009431.9 | AN45: =+AO45+ERI!BB51 -> 8816965.9 | AO45: =+AP45+ERI!BC51 -> 9048605.9 | AP45: =+AQ45+ERI!BD47 -> -26187562 | AQ45: =+AR45+ERI!BE51 -> -23085129 | AR45: =+AS45+ERI!BF51 -> -11531482 | AS45: =+ERI!BG51 -> -6522272 | AU45: =+ERI!BI51 -> 290436.49 | AV45: =+'NOTAS ERI'!BH179 -> -5354177.5 | AW45: =+'NOTAS ERI'!BI179 -> -5366628.5 | AX45: =+'NOTAS ERI'!BJ179 -> 9843075.7 | AY45: =+'NOTAS ERI'!BK179 -> 6161651.3 | AZ45: =+ERI!BO51 -> #REF! | BA45: =+ERI!BP51 -> #REF! | BB45: =+ERI!BQ51 -> #REF! | BC45: =+ERI!BR51 -> #REF! | BD45: =+'NOTAS ERI'!BP175 -> 2369930 | BE45: =+ERI!BT51 -> #REF! | BF45: =+ERI!BU51 -> #REF! | BH45: =+ERI!BW51 -> 1066515 | BI45: =+ERI!#REF!+ERI!#REF!+ERI!#REF!+ERI!#REF!+ERI!CC47+ERI!CB47+ERI!CA47+ERI!BZ47+ERI!BY47 -> #REF! | BJ45: =+ERI!#REF!+ERI!#REF!+ERI!#REF!+ERI!#REF!+ERI!CC47+ERI!CB47+ERI!CA47+ERI!BZ47 -> #REF! | BK45: =+ERI!#REF!+ERI!#REF!+ERI!#REF!+ERI!#REF!+ERI!CC47+ERI!CB47+ERI!CA47 -> #REF! | BL45: =+'NOTAS ERI'!#REF!+'NOTAS ERI'!#REF!+'NOTAS ERI'!#REF!+'NOTAS ERI'!#REF!+'NOTAS ERI'!BZ175+'NOTAS ERI'!BY175 -> #REF! | BM45: =+'NOTAS ERI'!#REF!+'NOTAS ERI'!#REF!+'NOTAS ERI'!#REF!+'NOTAS ERI'!#REF!+'NOTAS ERI'!BZ175 -> #REF! | BO45: =+'NOTAS ESF'!BK134 -> 0
B47: Total Patrimonio | F47: =SUM(F40:F46) -> 41584411 | H47: =SUM(H40:H46) -> 49330916 | I47: =SUM(I40:I46) -> 43222362 | J47: =SUM(J40:J46) -> 35695440 | K47: =SUM(K40:K46) -> 26038709 | L47: =SUM(L40:L46) -> 15487508 | M47: =SUM(M40:M46) -> 12724984 | N47: =SUM(N40:N46) -> 11942059 | O47: =SUM(O40:O46) -> 11055775 | ... S47: =SUM(S40:S46) -> 13388518 | U47: =SUM(U40:U46) -> 17403284 | V47: =SUM(V40:V46) -> 15836754 | W47: =SUM(W40:W46) -> 14052782 | X47: =SUM(X40:X46) -> 12685272 | Y47: =SUM(Y40:Y46) -> 12401440 | Z47: =SUM(Z40:Z46) -> 11482827 | AA47: =SUM(AA40:AA46) -> 9728771 | AB47: =SUM(AB40:AB46) -> 10139828 | ... AF47: =SUM(AF40:AF46) -> 10317684 | AH47: =SUM(AH40:AH46) -> 9186691.6 | AI47: =SUM(AI40:AI46) -> 13161181 | AJ47: =SUM(AJ40:AJ46) -> 11900652 | AK47: =SUM(AK40:AK46) -> 6827050.6 | AL47: =SUM(AL40:AL46) -> 10293029 | AM47: =SUM(AM40:AM46) -> 11241354 | AN47: =SUM(AN40:AN46) -> 12174757 | AO47: =SUM(AO40:AO46) -> 12406397 | ... AS47: =SUM(AS40:AS46) -> -3164480.5 | AU47: =SUM(AU40:AU46) -> 3357791.5 | AV47: =SUM(AV40:AV46) -> -2286822.5 | AW47: =SUM(AW40:AW46) -> -2299273.5 | AX47: =SUM(AX40:AX46) -> 12910431 | AY47: =SUM(AY40:AY46) -> 9229006.3 | AZ47: =SUM(AZ40:AZ46) -> #REF! | BA47: =SUM(BA40:BA46) -> #REF! | BB47: =SUM(BB40:BB46) -> #REF! | ... BF47: =SUM(BF40:BF46) -> #REF! | BH47: =SUM(BH40:BH46) -> 3066515 | BI47: =SUM(BI40:BI46) -> #REF! | BJ47: =SUM(BJ40:BJ46) -> #REF! | BK47: =SUM(BK40:BK46) -> #REF! | BL47: =SUM(BL40:BL46) -> #REF! | BM47: =SUM(BM40:BM46) -> #REF! | BO47: =SUM(BO40:BO46) -> 2000000
B49: Total Pasivo + Patrimonio | F49: =F36+F47 -> 1.4061731e+08 | H49: =H36+H47 -> 1.458645e+08 | I49: =I36+I47 -> 1.4665313e+08 | J49: =J36+J47 -> 1.2134925e+08 | K49: =K36+K47 -> 1.2162471e+08 | L49: =L36+L47 -> 1.0368991e+08 | M49: =M36+M47 -> 1.0129416e+08 | N49: =N36+N47 -> 93443117 | O49: =O36+O47 -> 1.0192369e+08 | ... S49: =S36+S47 -> 69057330 | U49: =U36+U47 -> 74355715 | V49: =V36+V47 -> 68643331 | W49: =W36+W47 -> 66495137 | X49: =X36+X47 -> 71277754 | Y49: =Y36+Y47 -> 65849265 | Z49: =Z36+Z47 -> 62586229 | AA49: =AA36+AA47 -> 57761111 | AB49: =AB36+AB47 -> 63488667 | ... AF49: =AF36+AF47 -> 48427369 | AH49: =AH36+AH47 -> 40074048 | AI49: =AI36+AI47 -> 69673255 | AJ49: =AJ36+AJ47 -> 71617876 | AK49: =AK36+AK47 -> 54978369 | AL49: =AL36+AL47 -> 61863386 | AM49: =AM36+AM47 -> 63369374 | AN49: =AN36+AN47 -> 1.0299026e+08 | AO49: =AO36+AO47 -> 98234656 | ... AS49: =AS36+AS47 -> 37232001 | AU49: =AU36+AU47 -> 44054429 | AV49: =AV36+AV47 -> 10528394 | AW49: =AW36+AW47 -> 49996276 | AX49: =AX36+AX47 -> 64151629 | AY49: =AY36+AY47 -> 41459709 | AZ49: =AZ36+AZ47 -> #REF! | BA49: =BA36+BA47 -> #REF! | BB49: =BB36+BB47 -> #REF! | ... BF49: =BF36+BF47 -> #REF! | BH49: =BH36+BH47 -> 25306581 | BI49: =BI36+BI47 -> #REF! | BJ49: =BJ36+BJ47 -> #REF! | BK49: =BK36+BK47 -> #REF! | BL49: =BL36+BL47 -> #REF! | BM49: =BM36+BM47 -> #REF! | BO49: =BO36+BO47 -> #REF!
F51: =+F19-F49 -> 0 | H51: =+H19-H49 -> 0 | I51: =+I19-I49 -> 0 | J51: =+J19-J49 -> 0 | K51: =+K19-K49 -> 0 | L51: =+L19-L49 -> 0 | M51: =+M19-M49 -> 0 | N51: =+N19-N49 -> 0 | O51: =+O19-O49 -> 0 | ... S51: =+S19-S49 -> 0 | U51: =+U19-U49 -> 0 | V51: =+V19-V49 -> 0 | W51: =+W19-W49 -> 0 | X51: =+X19-X49 -> 0 | Y51: =+Y19-Y49 -> 0 | Z51: =+Z19-Z49 -> 0 | AA51: =+AA19-AA49 -> 0 | AB51: =+AB19-AB49 -> 0 | ... AF51: =+AF19-AF49 -> 0 | AH51: =+AH19-AH49 -> -0.47352006 | AI51: =+AI19-AI49 -> #REF! | AJ51: =+AJ19-AJ49 -> #REF! | AK51: =+AK19-AK49 -> #REF! | AL51: =+AL19-AL49 -> #REF! | AM51: =+AM19-AM49 -> #REF! | AN51: =+AN19-AN49 -> #REF! | AO51: =+AO19-AO49 -> #REF! | ... AS51: =+AS19-AS49 -> #REF! | AU51: =+AU19-AU49 -> 0 | AV51: =+AV19-AV49 -> 0 | AW51: =+AW19-AW49 -> 0 | AX51: =+AX19-AX49 -> 0 | AY51: =+AY19-AY49 -> 0 | AZ51: =+AZ19-AZ49 -> #REF! | BA51: =+BA19-BA49 -> #REF! | BB51: =+BB19-BB49 -> #REF! | ... BF51: =+BF19-BF49 -> #REF! | BH51: =+BH19-BH49 -> 3.3527613e-08 | BI51: =+BI19-BI49 -> #REF! | BJ51: =+BJ19-BJ49 -> #REF! | BK51: =+BK19-BK49 -> #REF! | BL51: =+BL19-BL49 -> #REF! | BM51: =+BM19-BM49 -> #REF! | BO51: =+BO19-BO49 -> #REF!
B53: Representante Legal
B54: Representante Legal
B58: JIMMY ARCHILA SILVA
...

Sheet ERI
B2: =+ESF!B2 -> JELCOM SOLUCIONES EMPRESARIALES SAS
B3: =+ESF!B3 -> NIT. 901360819
B4: ESTADO DE RESULTADOS
B5: PARA LOS PERIODOS TERMINADOS
B7: INGRESOS | C7: Nota | E7: 01.01.2025 | F7: 01.12.2026 | G7: 01.11.2026 | H7: 01.10.2026 | I7: 01.09.2026 | J7: 01.08.2026 | K7: 01.07.2026 | L7: 01.06.2026 | M7: 01.05.2026 | N7: 01.04.2026 | O7: 01.03.2026 | P7: 01.02.2026 | Q7: 01.01.2026 | S7: 01.01.2025 | T7: 01.12.2025 | U7: 01.11.2025 | V7: 01.10.2025 | W7: 01.09.2025 | X7: 01.08.2025 | Y7: 01.07.2025 | Z7: 01.06.2025 | AA7: 01.05.2025 | AB7: 01.04.2025 | AC7: 01.03.2025 | AD7: 01.02.2025 | AE7: 01.01.2025 | AG7: 01.01.2024 | AH7: 01.12.2024 | AI7: 01.11.2024 | AJ7: 01.10.2024 | AK7: 01.09.2024 | AL7: 01.08.2024 | AM7: 01.07.2024 | AN7: 01.06.2024 | AO7: 01.05.2024 | AP7: 01.04.2024 | AQ7: 01.03.2024 | AR7: 01.02.2024 | AS7: 01.01.2024 | AU7: 01.01.2023 | AV7: 01.12.2023 | AW7: 01.11.2023 | AX7: 01.10.2023 | AY7: 01.09.2023 | AZ7: 01.08.2023 | BA7: 01.07.2023 | BB7: 01.06.2023 | BC7: 01.05.2023 | BD7: 01.04.2023 | BE7: 01.03.2023 | BF7: 01.02.2023 | BG7: 01.01.2023 | BI7: 01.01.2022 | BJ7: 01.12.2022 | BK7: 01.11.2022 | BL7: 01.10.2022 | BM7: 01.09.2022 | BN7: 01.08.2022 | BO7: 01.07.2022 | BP7: 01.06.2022 | BQ7: 01.05.2022 | BR7: 01.04.2019 | BS7: 01.03.2020 | BT7: 01.02.2021 | BU7: 01.01.2022 | BW7: 01.01.2021 | BX7: 01.10.2021 | BY7: 01.09.2021 | BZ7: 01.08.2021 | CA7: 01.07.2021 | CB7: 01.06.2021 | CC7: 01.05.2021 | CE7: 01.12.2020 | CF7: 01.12.2017 | CH7: 01.12.2016
E8: 31.12.2025 | F8: 31.12.2026 | G8: 30.11.2026 | H8: 31.10.2026 | I8: 30.09.2026 | J8: 31.08.2026 | K8: 31.07.2026 | L8: 30.06.2026 | M8: 31.05.2026 | N8: 30.04.2026 | O8: 31.03.2026 | P8: 28.02.2026 | Q8: 31.01.2026 | S8: 31.12.2025 | T8: 31.12.2025 | U8: 30.11.2025 | V8: 31.10.2025 | W8: 30.09.2025 | X8: 31.08.2025 | Y8: 31.07.2025 | Z8: 30.06.2025 | AA8: 31.05.2025 | AB8: 30.04.2025 | AC8: 31.03.2025 | AD8: 28.02.2025 | AE8: 31.01.2025 | AG8: 31.12.2024 | AH8: 30.12.2024 | AI8: 30.11.2024 | AJ8: 31.10.2024 | AK8: 30.09.2024 | AL8: 31.08.2024 | AM8: 31.07.2024 | AN8: 30.06.2024 | AO8: 31.05.2024 | AP8: 30.04.2024 | AQ8: 31.03.2024 | AR8: 28.02.2024 | AS8: 31.01.2024 | AU8: 31.12.2023 | AV8: 31.12.2023 | AW8: 30.11.2023 | AX8: 31.10.2023 | AY8: 30.09.2023 | AZ8: 31.08.2023 | BA8: 31.07.2023 | BB8: 30.06.2023 | BC8: 31.05.2023 | BD8: 30.04.2023 | BE8: 31.03.2023 | BF8: 28.02.2023 | BG8: 01.01.2023 | BI8: 31.12.2022 | BJ8: 31.12.2022 | BK8: 30.11.2022 | BL8: 31.10.2022 | BM8: 30.09.2022 | BN8: 30.08.2022 | BO8: 31.07.2022 | BP8: 30.06.2022 | BQ8: 30.05.2022 | BR8: 30.04.2022 | BS8: 31.03.2022 | BT8: 28.02.2022 | BU8: 31.01.2022 | BW8: 31.12.2021 | BX8: 30.10.2021 | BY8: 30.09.2021 | BZ8: 30.08.2021 | CA8: 30.07.2021 | CB8: 30.06.2021 | CC8: 31.05.2021 | CE8: 31.12.2020 | CF8: 31.12.2017 | CH8: 31.12.2016
B10: INGRESOS OPERACIONALES | C10: 12 | E10: =SUM(E12:E13) -> 45023259 | F10: =SUM(F12:F13) -> 0 | G10: =SUM(G12:G13) -> 0 | H10: =SUM(H12:H13) -> 0 | I10: =SUM(I12:I13) -> 0 | J10: =SUM(J12:J13) -> 0 | K10: =SUM(K12:K13) -> 0 | L10: =SUM(L12:L13) -> 0 | ... Q10: =SUM(Q12:Q13) -> 45023259 | S10: =SUM(S12:S13) -> 370322671 | T10: =SUM(T12:T13) -> 41398469 | U10: =SUM(U12:U13) -> 42018469 | V10: =SUM(V12:V13) -> 43654871 | W10: =SUM(W12:W13) -> 42958469 | X10: =SUM(X12:X13) -> 31018469 | Y10: =SUM(Y12:Y13) -> 29178469 | Z10: =SUM(Z12:Z13) -> 28798469 | ... AE10: =SUM(AE12:AE13) -> 1510000 | AG10: =SUM(AG12:AG13) -> 95609587 | AH10: =+AH12+AH13 -> 6910000 | AI10: =+AI12+AI13 -> 7309587 | AJ10: =+AJ12+AJ13 -> 6910000 | AK10: =+AK12+AK13 -> 6910000 | AL10: =+AL12+AL13 -> 7910000 | AM10: =+AM12+AM13 -> 9270000 | AN10: =+AN12+AN13 -> 7020000 | AO10: =+AO12+AO13 -> 9740000 | ... AS10: =+AS12+AS13 -> 8230000 | AU10: =SUM(AU12:AU13) -> 102813014 | AV10: =SUM(AV12:AV13) -> 8185423 | AW10: =SUM(AW12:AW13) -> 8185423 | AX10: =SUM(AX12:AX13) -> 11760000 | AY10: =SUM(AY12:AY13) -> 2360000 | AZ10: =SUM(AZ12:AZ13) -> 5890000 | BA10: =SUM(BA12:BA13) -> 6360000 | BB10: =SUM(BB12:BB13) -> 7080000 | ... BG10: =SUM(BG12:BG13) -> 2940168 | BI10: =SUM(BI12:BI13) -> 47784225 | BJ10: =SUM(BJ12:BJ13) -> 6640168 | BK10: =SUM(BK12:BK13) -> 1970000 | BL10: =SUM(BL12:BL13) -> 3795000 | BM10: =SUM(BM12:BM13) -> 18668403 | BN10: =SUM(BN12:BN13) -> 11595735 | BO10: =SUM(BO12:BO13) -> 0 | BP10: =SUM(BP12:BP13) -> 0 | ... BU10: =SUM(BU12:BU13) -> 1000000 | BW10: =SUM(BW12:BW13) -> 18444000 | BX10: =SUM(BX12:BX13) -> #REF! | BY10: =SUM(BY12:BY13) -> #REF! | BZ10: =SUM(BZ12:BZ13) -> #REF! | CA10: =SUM(CA12:CA13) -> #REF! | CB10: =SUM(CB12:CB13) -> #REF! | CC10: =SUM(CC12:CC13) -> #REF! | CE10: =SUM(CE12:CE13) -> 0 | CF10: =SUM(CF12:CF13) -> #REF! | CH10: =SUM(CH12:CH13) -> #REF!
B12: =+'NOTAS ERI'!A37 -> Actividades de Centro de Llamadas | E12: =SUM(F12:Q12) -> 66237137 | F12: =+'NOTAS ERI'!C10 -> 0 | G12: =+'NOTAS ERI'!D10 -> 0 | H12: =+'NOTAS ERI'!E10 -> 0 | I12: =+'NOTAS ERI'!F10 -> 0 | J12: =+'NOTAS ERI'!G10 -> 0 | K12: =+'NOTAS ERI'!H10 -> 0 | L12: =+'NOTAS ERI'!I10 -> 0 | M12: =+'NOTAS ERI'!J10 -> 0 | ... Q12: =+'NOTAS ERI'!N10 -> 66237137 | S12: =SUM(T12:AE12) -> 399036750 | T12: =+'NOTAS ERI'!Q10 -> 41398469 | U12: =+'NOTAS ERI'!R10 -> 42018469 | V12: =+'NOTAS ERI'!S10 -> 43654871 | W12: =+'NOTAS ERI'!T10 -> 42958469 | X12: =+'NOTAS ERI'!U10 -> 31018469 | Y12: =+'NOTAS ERI'!V10 -> 56826938 | Z12: =+'NOTAS ERI'!W10 -> 28798469 | AA12: =+'NOTAS ERI'!X10 -> 26614079 | ... AE12: =+'NOTAS ERI'!AB10 -> 1510000 | AG12: =SUM(AH12:AS12) -> 96769587 | AH12: =+'NOTAS ERI'!AE10 -> 6910000 | AI12: =+'NOTAS ERI'!AF10 -> 7309587 | AJ12: =+'NOTAS ERI'!AG10 -> 7530000 | AK12: =+'NOTAS ERI'!AH10 -> 6910000 | AL12: =+'NOTAS ERI'!AI10 -> 7910000 | AM12: =+'NOTAS ERI'!AJ10 -> 9270000 | AN12: =+'NOTAS ERI'!AK10 -> 7020000 | AO12: =+'NOTAS ERI'!AL10 -> 9740000 | ... AS12: =+'NOTAS ERI'!AP10 -> 8230000 | AU12: =SUM(AV12:BG12) -> 105983014 | AV12: =+'NOTAS ERI'!AS10 -> 8185423 | AW12: =+'NOTAS ERI'!AT10 -> 8185423 | AX12: =+'NOTAS ERI'!AU10 -> 13260000 | AY12: =+'NOTAS ERI'!AV10 -> 2360000 | AZ12: =+'NOTAS ERI'!AW10 -> 6360000 | BA12: =+'NOTAS ERI'!AX10 -> 6360000 | BB12: =+'NOTAS ERI'!AY10 -> 7080000 | BC12: =+'NOTAS ERI'!AZ10 -> 42140000 | ... BG12: =+'NOTAS ERI'!BD10 -> 2940168 | BI12: =SUM(BJ12:BU12) -> 51027964 | BJ12: =+'NOTAS ERI'!BG10 -> 6640168 | BK12: =+'NOTAS ERI'!BH10 -> 1970000 | BL12: =+'NOTAS ERI'!BI10 -> 3795000 | BM12: =+'NOTAS ERI'!BJ10 -> 18668403 | BN12: =+'NOTAS ERI'!BK10 -> 12733235 | BO12: =+'NOTAS ERI'!BL10 -> 0 | BP12: =+'NOTAS ERI'!BM10 -> 0 | BQ12: =+'NOTAS ERI'!BN10 -> 1106239 | ... BU12: =+'NOTAS ERI'!BR10 -> 1000000 | BW12: =+'NOTAS ERI'!BT10 -> 29847361 | BX12: =+'NOTAS ERI'!BU37 -> 0 | BY12: =+'NOTAS ERI'!BV37 -> 0 | BZ12: =+'NOTAS ERI'!BW37 -> 0 | CA12: =+'NOTAS ERI'!BX37 -> 0 | CB12: =+'NOTAS ERI'!BY37 -> 0 | CC12: =+'NOTAS ERI'!BZ37 -> 0 | CE12: =+'NOTAS ERI'!CB37 -> 0 | CF12: =+'NOTAS ERI'!#REF! -> #REF! | CH12: =+'NOTAS ERI'!#REF! -> #REF!
B13: Devoluciones y Descuentos | E13: =SUM(F13:Q13) -> -21213878 | F13: =+'NOTAS ERI'!C38 -> 0 | G13: =+'NOTAS ERI'!D38 -> 0 | H13: =+'NOTAS ERI'!E38 -> 0 | I13: =+'NOTAS ERI'!F38 -> 0 | J13: =+'NOTAS ERI'!G38 -> 0 | K13: =+'NOTAS ERI'!H38 -> 0 | L13: =+'NOTAS ERI'!I38 -> 0 | M13: =+'NOTAS ERI'!J38 -> 0 | ... Q13: =+'NOTAS ERI'!N38 -> -21213878 | S13: =SUM(T13:AE13) -> -28714079 | T13: =+'NOTAS ERI'!Q38 -> 0 | U13: =+'NOTAS ERI'!R38 -> 0 | V13: =+'NOTAS ERI'!S38 -> 0 | W13: =+'NOTAS ERI'!T38 -> 0 | X13: =+'NOTAS ERI'!U38 -> 0 | Y13: =+'NOTAS ERI'!V38 -> -27648469 | Z13: =+'NOTAS ERI'!W38 -> 0 | AA13: =+'NOTAS ERI'!X38 -> 0 | ... AE13: =+'NOTAS ERI'!AB38 -> 0 | AG13: =+'NOTAS ERI'!AD38 -> -1160000 | AH13: =+'NOTAS ERI'!AE38 -> 0 | AI13: =+'NOTAS ERI'!AF38 -> 0 | AJ13: =+'NOTAS ERI'!AG38 -> -620000 | AK13: =+'NOTAS ERI'!AH38 -> 0 | AL13: =+'NOTAS ERI'!AI38 -> 0 | AM13: =+'NOTAS ERI'!AJ38 -> 0 | AN13: =+'NOTAS ERI'!AK38 -> 0 | ... AS13: =+'NOTAS ERI'!AP38 -> 0 | AU13: =SUM(AV13:BG13) -> -3170000 | AV13: =+'NOTAS ERI'!AS38 -> 0 | AW13: =+'NOTAS ERI'!AT38 -> 0 | AX13: =+'NOTAS ERI'!AU38 -> -1500000 | AY13: =+'NOTAS ERI'!AV38 -> 0 | AZ13: =+'NOTAS ERI'!AW38 -> -470000 | BA13: =+'NOTAS ERI'!AX38 -> 0 | BB13: =+'NOTAS ERI'!AY38 -> 0 | BC13: =+'NOTAS ERI'!AZ38 -> -200000 | ... BG13: =+'NOTAS ERI'!BD38 -> 0 | BI13: =SUM(BJ13:BU13) -> -3243739 | BJ13: =+'NOTAS ERI'!BG38 -> 0 | BK13: =+'NOTAS ERI'!BH38 -> 0 | BL13: =+'NOTAS ERI'!BI38 -> 0 | BM13: =+'NOTAS ERI'!BJ38 -> 0 | BN13: =+'NOTAS ERI'!BK38 -> -1137500 | BO13: =+'NOTAS ERI'!BL38 -> 0 | BP13: =+'NOTAS ERI'!BM38 -> 0 | BQ13: =+'NOTAS ERI'!BN38 -> -1106239 | ... BU13: =+'NOTAS ERI'!BR38 -> 0 | BW13: =+'NOTAS ERI'!BT38 -> -11403361 | BX13: =+'NOTAS ERI'!#REF! -> #REF! | BY13: =+'NOTAS ERI'!#REF! -> #REF! | BZ13: =+'NOTAS ERI'!#REF! -> #REF! | CA13: =+'NOTAS ERI'!#REF! -> #REF! | CB13: =+'NOTAS ERI'!#REF! -> #REF! | CC13: =+'NOTAS ERI'!#REF! -> #REF! | CE13: 0 | CF13: =+'NOTAS ERI'!#REF! -> #REF! | CH13: =+'NOTAS ERI'!#REF! -> #REF!
E14: =SUM(R14:AM14) -> 0 | F14: =SUM(H14:AC14) -> 0 | G14: =SUM(I14:AD14) -> 0 | H14: =SUM(J14:AE14) -> 0 | I14: =SUM(K14:AF14) -> 0 | J14: =SUM(L14:AG14) -> 0 | K14: =SUM(M14:AH14) -> 0 | L14: =SUM(N14:AI14) -> 0 | M14: =SUM(O14:AJ14) -> 0 | ... Q14: =SUM(S14:AN14) -> 0 | S14: =SUM(T14:AO14) -> 0 | T14: =SUM(U14:AF14) -> 0 | U14: =SUM(V14:AG14) -> 0 | V14: =SUM(W14:AH14) -> 0 | W14: =SUM(X14:AI14) -> 0 | X14: =SUM(Y14:AJ14) -> 0 | Y14: =SUM(Z14:AK14) -> 0 | Z14: =SUM(AA14:AL14) -> 0 | AA14: =SUM(AB14:AM14) -> 0 | ... AE14: =SUM(AF14:AQ14) -> 0 | AG14: =SUM(AH14:AS14) -> 0 | AU14: =SUM(BB14:BG14) -> 0
B15: INGRESOS NO OPERACIONALES | C15: 15 | E15: =SUM(E17) -> 0 | F15: =SUM(F17) -> 0 | G15: =SUM(G17) -> 0 | H15: =SUM(H17) -> 0 | I15: =SUM(I17) -> 0 | J15: =SUM(J17) -> 0 | K15: =SUM(K17) -> 0 | L15: =SUM(L17) -> 0 | ... Q15: =SUM(Q17) -> 0 | S15: =SUM(S17) -> 2492.75 | T15: =SUM(T17) -> 0 | U15: =SUM(U17) -> 0 | V15: =SUM(V17) -> 0 | W15: =SUM(W17) -> 0 | X15: =SUM(X17) -> 0 | Y15: =SUM(Y17) -> 0 | Z15: =SUM(Z17) -> 0 | ... AE15: =SUM(AE17) -> 840.75 | AG15: =SUM(AG17) -> 2182 | AH15: =+AH16+AH18+AH17 -> 638 | AI15: =+AI16+AI18+AI17 -> 0 | AJ15: =+AJ16+AJ18+AJ17 -> 0 | AK15: =+AK16+AK18+AK17 -> 879 | AL15: =+AL16+AL18+AL17 -> 0 | AM15: =+AM16+AM18+AM17 -> 0 | AN15: =+AN16+AN18+AN17 -> 369 | AO15: =+AO16+AO18+AO17 -> 296 | ... AS15: =+AS16+AS18+AS17 -> 0 | AU15: =SUM(AU17) -> 200 | AV15: =+AV16+AV18+AV17 -> 0 | AW15: =+AW16+AW18+AW17 -> 0 | AX15: =+AX16+AX18+AX17 -> 0 | AY15: =+AY16+AY18+AY17 -> 0 | AZ15: =+AZ16+AZ18+AZ17 -> 400 | BA15: =+BA16+BA18+BA17 -> 0 | BB15: =+BB16+BB18 -> 0 | BC15: =+BC16+BC18 -> 0 | BD15: =+BD16+BD18 -> 0 | BE15: =+BE16+BE18 -> 0 | BF15: =+BF16+BF18 -> 0 | BG15: =+BG16+BG18 -> 0 | BI15: =+BI16+BI18 -> 0 | BJ15: =+BJ16+BJ18 -> 0 | BK15: =+BK16+BK18 -> 0 | BL15: =+BL16+BL18 -> 0 | BM15: =+BM16+BM18 -> 0 | BN15: =+BN16+BN18 -> 0 | BO15: =+BO16+BO18 -> 0 | BP15: =+BP16+BP18 -> 0 | ... BU15: =+BU16+BU18 -> 0 | BW15: =+BW16+BW18 -> 0 | BX15: =+BX16+BX18 -> 0 | BY15: =+BY16+BY18 -> 0 | BZ15: =+BZ16+BZ18 -> 0 | CA15: =+CA16+CA18 -> 0 | CB15: =+CB16+CB18 -> 0 | CC15: =+CC16+CC18 -> 0 | CE15: =+CE16+CE18 -> #REF! | CF15: =+CF16+CF18 -> #REF! | CH15: =+CH16 -> #REF!
B16: Subsidio de Nomina | E16: =SUM(R16:AM16) -> 0 | F16: =SUM(H16:AC16) -> 0 | G16: =SUM(I16:AD16) -> 0 | H16: =SUM(J16:AE16) -> 0 | I16: =SUM(K16:AF16) -> 0 | J16: =SUM(L16:AG16) -> 0 | K16: =SUM(M16:AH16) -> 0 | L16: =SUM(N16:AI16) -> 0 | M16: =SUM(O16:AJ16) -> 0 | ... Q16: =SUM(S16:AN16) -> 0 | S16: =SUM(T16:AO16) -> 0 | T16: =SUM(U16:AF16) -> 0 | U16: =SUM(V16:AG16) -> 0 | V16: =SUM(W16:AH16) -> 0 | W16: =SUM(X16:AI16) -> 0 | X16: =SUM(Y16:AJ16) -> 0 | Y16: =SUM(Z16:AK16) -> 0 | Z16: =SUM(AA16:AL16) -> 0 | AA16: =SUM(AB16:AM16) -> 0 | ... AE16: =SUM(AF16:AQ16) -> 0 | AG16: =SUM(AH16:AS16) -> 0 | AU16: =SUM(BB16:BG16) -> 0 | AZ16: =+'NOTAS ERI'!AX41 -> 200 | BA16: =+'NOTAS ERI'!AY41 -> 0 | BB16: =+'NOTAS ERI'!AZ41 -> 0 | BC16: =+'NOTAS ERI'!BA41 -> 0 | BD16: =+'NOTAS ERI'!BB41 -> 0 | BE16: =+'NOTAS ERI'!BC41 -> 0 | BF16: =+'NOTAS ERI'!BD41 -> 0 | BG16: =+'NOTAS ERI'!BE41 -> 0 | BI16: =+'NOTAS ERI'!BF41 -> 0 | BJ16: =+'NOTAS ERI'!BG41 -> 0 | BK16: =+'NOTAS ERI'!BH41 -> 0 | BL16: =+'NOTAS ERI'!BI41 -> 0 | BM16: =+'NOTAS ERI'!BJ41 -> 0 | BN16: =+'NOTAS ERI'!BK41 -> 0 | BO16: =+'NOTAS ERI'!BL41 -> 0 | BP16: =+'NOTAS ERI'!BM41 -> 0 | ... BU16: =+'NOTAS ERI'!BR41 -> 0 | BW16: =+'NOTAS ERI'!BT41 -> 0 | BX16: =+'NOTAS ERI'!BU41 -> 0 | BY16: =+'NOTAS ERI'!BV41 -> 0 | BZ16: =+'NOTAS ERI'!BW41 -> 0 | CA16: =+'NOTAS ERI'!BX41 -> 0 | CB16: =+'NOTAS ERI'!BY41 -> 0 | CC16: =+'NOTAS ERI'!BZ41 -> 0 | CE16: =+'NOTAS ERI'!CB41 -> 0 | CF16: =+'NOTAS ERI'!#REF! -> #REF! | CH16: =+'NOTAS ERI'!#REF! -> #REF!
B17: Ajuste al peso | E17: =SUM(F17:Q17) -> 0 | F17: =+'NOTAS ERI'!C41 -> 0 | G17: =+'NOTAS ERI'!D41 -> 0 | H17: =+'NOTAS ERI'!E41 -> 0 | I17: =+'NOTAS ERI'!F41 -> 0 | J17: =+'NOTAS ERI'!G41 -> 0 | K17: =+'NOTAS ERI'!H41 -> 0 | L17: =+'NOTAS ERI'!I41 -> 0 | M17: =+'NOTAS ERI'!J41 -> 0 | ... Q17: =+'NOTAS ERI'!N41 -> 0 | S17: =SUM(T17:AE17) -> 2492.75 | T17: =+'NOTAS ERI'!Q41 -> 0 | U17: =+'NOTAS ERI'!R41 -> 0 | V17: =+'NOTAS ERI'!S41 -> 0 | W17: =+'NOTAS ERI'!T41 -> 0 | X17: =+'NOTAS ERI'!U41 -> 0 | Y17: =+'NOTAS ERI'!V41 -> 0 | Z17: =+'NOTAS ERI'!W41 -> 0 | AA17: =+'NOTAS ERI'!X41 -> 839 | ... AE17: =+'NOTAS ERI'!AB41 -> 840.75 | AG17: =SUM(AH17:AS17) -> 2182 | AH17: =+'NOTAS ERI'!AE41 -> 638 | AK17: =+'NOTAS ERI'!AH41 -> 879 | AN17: =+'NOTAS ERI'!AK41 -> 369 | AO17: =+'NOTAS ERI'!AL41 -> 296 | AU17: =SUM(AV17:BG17) -> 200 | AZ17: =+'NOTAS ERI'!AX42 -> 200
B18: Reintegro Costos y gastos | E18: =SUM(AE18:AM18) -> 0 | F18: =SUM(U18:AC18) -> 0 | G18: =SUM(V18:AD18) -> 0 | H18: =SUM(W18:AE18) -> 0 | I18: =SUM(X18:AF18) -> 0 | J18: =SUM(Y18:AG18) -> 0 | K18: =SUM(Z18:AH18) -> 0 | L18: =SUM(AA18:AI18) -> 0 | M18: =SUM(AB18:AJ18) -> 0 | ... Q18: =SUM(AF18:AN18) -> 0 | S18: =SUM(AG18:AO18) -> 0 | T18: =SUM(X18:AF18) -> 0 | U18: =SUM(Y18:AG18) -> 0 | V18: =SUM(Z18:AH18) -> 0 | W18: =SUM(AA18:AI18) -> 0 | X18: =SUM(AB18:AJ18) -> 0 | Y18: =SUM(AC18:AK18) -> 0 | Z18: =SUM(AD18:AL18) -> 0 | AA18: =SUM(AE18:AM18) -> 0 | ... AE18: =SUM(AI18:AQ18) -> 0 | AG18: =SUM(AK18:AS18) -> 0 | AH18: 0 | AI18: 0 | AJ18: 0 | AK18: 0 | AL18: 0 | AM18: 0 | AN18: 0 | AO18: 0 | AP18: 0 | AQ18: 0 | AR18: 0 | AS18: 0 | AU18: =SUM(BB18:BG18) -> 0 | AV18: 0 | AW18: 0 | AX18: 0 | AY18: 0 | AZ18: 0 | BA18: 0 | BB18: 0 | BC18: 0 | BD18: 0 | BE18: 0 | BF18: 0 | BG18: 0 | BI18: 0 | BJ18: 0 | BK18: 0 | BL18: 0 | BM18: 0 | BN18: 0 | BO18: 0 | BP18: 0 | BQ18: 0 | BR18: 0 | BS18: 0 | BT18: 0 | BU18: 0 | BW18: 0 | BX18: 0 | BY18: 0 | BZ18: 0 | CA18: 0 | CB18: 0 | CC18: 0 | CE18: =+'NOTAS ERI'!#REF! -> #REF! | CF18: 0
AU19: =SUM(BB19:BG19) -> 0
B20: TOTAL INGRESOS | E20: =+E10+E15 -> 45023259 | F20: =+F10+F15 -> 0 | G20: =+G10+G15 -> 0 | H20: =+H10+H15 -> 0 | I20: =+I10+I15 -> 0 | J20: =+J10+J15 -> 0 | K20: =+K10+K15 -> 0 | L20: =+L10+L15 -> 0 | ... Q20: =+Q10+Q15 -> 45023259 | S20: =+S10+S15 -> 3.7032516e+08 | T20: =+T10+T15 -> 41398469 | U20: =+U10+U15 -> 42018469 | V20: =+V10+V15 -> 43654871 | W20: =+W10+W15 -> 42958469 | X20: =+X10+X15 -> 31018469 | Y20: =+Y10+Y15 -> 29178469 | Z20: =+Z10+Z15 -> 28798469 | ... AE20: =+AE10+AE15 -> 1510840.8 | AG20: =+AG10+AG15 -> 95611769 | AH20: =+'NOTAS ERI'!AE44 -> 6910638 | AI20: =+'NOTAS ERI'!AF44 -> 7309587 | AJ20: =+'NOTAS ERI'!AG44 -> 6910000 | AK20: =+'NOTAS ERI'!AH44 -> 6910879 | AL20: =+'NOTAS ERI'!AI44 -> 7910000 | AM20: =+AM10+AM15 -> 9270000 | AN20: =+AN10+AN15 -> 7020369 | AO20: =+AO10+AO15 -> 9740296 | AP20: =+AP10+AP15 -> 7020000 | AQ20: =+AQ10+AQ15 -> 10820000 | AR20: =+AR10+AR15 -> 7560000 | AS20: =+AS10+AS15 -> 8230000 | AU20: =+AU10+AU15 -> 102813214 | AV20: =+AV10+AV15 -> 8185423 | AW20: =+AW10+AW15 -> 8185423 | AX20: =+AX10+AX15 -> 11760000 | AY20: =+AY10+AY15 -> 2360000 | AZ20: =+AZ10+AZ15 -> 5890400 | BA20: =+BA10+BA15 -> 6360000 | BB20: =+BB10+BB15 -> 7080000 | ... BG20: =+BG10+BG15 -> 2940168 | BI20: =+BI10+BI15 -> 47784225 | BJ20: =+BJ10+BJ15 -> 6640168 | BK20: =+BK10+BK15 -> 1970000 | BL20: =+BL10+BL15 -> 3795000 | BM20: =+BM10+BM15 -> 18668403 | BN20: =+BN10+BN15 -> 11595735 | BO20: =+BO10+BO15 -> 0 | BP20: =+BP10+BP15 -> 0 | ... BU20: =+BU10+BU15 -> 1000000 | BW20: =+BW10+BW15 -> 18444000 | BX20: =+BX10+BX15 -> #REF! | BY20: =+BY10+BY15 -> #REF! | BZ20: =+BZ10+BZ15 -> #REF! | CA20: =+CA10+CA15 -> #REF! | CB20: =+CB10+CB15 -> #REF! | CC20: =+CC10+CC15 -> #REF! | CE20: =+CE10+CE15 -> #REF! | CF20: =+CF10+CF15 -> #REF! | CH20: =+CH10+CH16 -> #REF!
AU21: =SUM(BB21:BG21) -> 0
AU22: =SUM(BB22:BG22) -> 0
B23: UTILIDAD OPERACIONAL | E23: =+E20 -> 45023259 | F23: =+F20 -> 0 | G23: =+G20 -> 0 | H23: =+H20 -> 0 | I23: =+I20 -> 0 | J23: =+J20 -> 0 | K23: =+K20 -> 0 | L23: =+L20 -> 0 | ... Q23: =+Q20 -> 45023259 | S23: =+S20 -> 3.7032516e+08 | T23: =+T20 -> 41398469 | U23: =+U20 -> 42018469 | V23: =+V20 -> 43654871 | W23: =+W20 -> 42958469 | X23: =+X20 -> 31018469 | Y23: =+Y20 -> 29178469 | Z23: =+Z20 -> 28798469 | ... AE23: =+AE20 -> 1510840.8 | AG23: =+AG20 -> 95611769 | AH23: =+AH20 -> 6910638 | AI23: =+AI20 -> 7309587 | AJ23: =+AJ20 -> 6910000 | AK23: =+AK20 -> 6910879 | AL23: =+AL20 -> 7910000 | AM23: =+AM20 -> 9270000 | AN23: =+AN20 -> 7020369 | ... AS23: =+AS20 -> 8230000 | AU23: =+AU20 -> 102813214 | AV23: =+AV20 -> 8185423 | AW23: =+AW20 -> 8185423 | AX23: =+AX20 -> 11760000 | AY23: =+AY20 -> 2360000 | AZ23: =+AZ20 -> 5890400 | BA23: =+BA20 -> 6360000 | BB23: =+BB20 -> 7080000 | ... BG23: =+BG20 -> 2940168 | BI23: =+BI20 -> 47784225 | BJ23: =+BJ20 -> 6640168 | BK23: =+BK20 -> 1970000 | BL23: =+BL20 -> 3795000 | BM23: =+BM20 -> 18668403 | BN23: =+BN20 -> 11595735 | BO23: =+BO20 -> 0 | BP23: =+BP20 -> 0 | ... BU23: =+BU20 -> 1000000 | BW23: =+BW20 -> 18444000 | BX23: =+BX20 -> #REF! | BY23: =+BY20 -> #REF! | BZ23: =+BZ20 -> #REF! | CA23: =+CA20 -> #REF! | CB23: =+CB20 -> #REF! | CC23: =+CC20 -> #REF! | CE23: =+CE20 -> #REF! | CF23: =+CF20 -> #REF! | CH23: =+CH20 -> #REF!
AU24: =SUM(BB24:BG24) -> 0
AU25: =SUM(BB25:BG25) -> 0
B26: GASTOS DE ADMINISTRACION | C26: 13 | E26: =SUM(E27:E39) -> 52324866 | F26: =SUM(F27:F39) -> 0 | G26: =SUM(G27:G39) -> 0 | H26: =SUM(H27:H39) -> 0 | I26: =SUM(I27:I39) -> 0 | J26: =SUM(J27:J39) -> 0 | K26: =SUM(K27:K39) -> 0 | L26: =SUM(L27:L39) -> 0 | ... Q26: =SUM(Q27:Q39) -> 52324866 | S26: =SUM(S27:S39) -> 307545073 | T26: =SUM(T27:T39) -> 31453969 | U26: =SUM(U27:U39) -> 30123840 | V26: =SUM(V27:V39) -> 28240530 | W26: =SUM(W27:W39) -> 26333745 | X26: =SUM(X27:X39) -> 26427628 | Y26: =SUM(Y27:Y39) -> 27604064 | Z26: =SUM(Z27:Z39) -> 27002069 | ... AE26: =SUM(AE27:AE39) -> 7496371 | AG26: =SUM(AG27:AG39) -> 79716729 | AH26: =SUM(AH27:AH38) -> 4303506 | AI26: =SUM(AI27:AI38) -> 4349284 | AJ26: =SUM(AJ27:AJ38) -> 4568899 | AK26: =SUM(AK27:AK38) -> 6292759 | AL26: =SUM(AL27:AL38) -> 6292759 | AM26: =SUM(AM27:AM38) -> 6386179.2 | AN26: =SUM(AN27:AN38) -> 6544793 | AO26: =SUM(AO27:AO38) -> 8358309.7 | ... AS26: =SUM(AS27:AS38) -> 6321076 | AU26: =SUM(AU27:AU39) -> 90396886 | AV26: =SUM(AV27:AV38) -> 8962817 | AW26: =SUM(AW27:AW38) -> 6730050.1 | AX26: =SUM(AX27:AX38) -> 6549541 | AY26: =SUM(AY27:AY38) -> 5670950 | AZ26: =SUM(AZ27:AZ38) -> 6701895.1 | BA26: =SUM(BA27:BA38) -> 6825244 | BB26: =SUM(BB27:BB38) -> 7165691 | BC26: =SUM(BC27:BC38) -> 6568550 | ... BG26: =SUM(BG27:BG38) -> 9316704 | BI26: =SUM(BI27:BI39) -> 47493789 | BJ26: =+BJ28+BJ33+BJ34+BJ36+BJ38 -> #REF! | BK26: =+BK28+BK33+BK34+BK36+BK38 -> #REF! | BL26: =+BL28+BL33+BL34+BL36+BL38 -> #REF! | BM26: =+BM28+BM33+BM34+BM36+BM38 -> #REF! | BN26: =+BN28+BN33+BN34+BN36+BN38 -> #REF! | BO26: =+BO28+BO33+BO34+BO36+BO38 -> #REF! | BP26: =+BP28+BP33+BP34+BP36+BP38 -> #REF! | BQ26: =+BQ28+BQ33+BQ34+BQ36+BQ38 -> #REF! | ... BT26: =+BT28+BT33+BT34+BT36+BT38 -> #REF! | BU26: =+BU28+BU33+BU34+BU36+BU38+BU35+BU37 -> #REF! | BW26: =SUM(BW27:BW38) -> #REF! | BX26: =SUM(BX27:BX38) -> #REF! | BY26: =SUM(BY27:BY38) -> #REF! | BZ26: =SUM(BZ27:BZ38) -> #REF! | CA26: =SUM(CA27:CA38) -> #REF! | CB26: =SUM(CB27:CB38) -> #REF! | CC26: =SUM(CC27:CC38) -> #REF! | CE26: =SUM(CE27:CE38) -> #REF! | CF26: =SUM(CF27:CF38) -> #REF! | CH26: =SUM(CH27:CH38) -> #REF!
B28: Gastos de Personal | E28: =SUM(F28:Q28) -> 28343153 | F28: =+'NOTAS ERI'!C48 -> 0 | G28: =+'NOTAS ERI'!D48 -> 0 | H28: =+'NOTAS ERI'!E48 -> 0 | I28: =+'NOTAS ERI'!F48 -> 0 | J28: =+'NOTAS ERI'!G48 -> 0 | K28: =+'NOTAS ERI'!H48 -> 0 | L28: =+'NOTAS ERI'!I48 -> 0 | M28: =+'NOTAS ERI'!J48 -> 0 | ... Q28: =+'NOTAS ERI'!N48 -> 28343153 | S28: =SUM(T28:AE28) -> 274839697 | T28: =+'NOTAS ERI'!Q48 -> 25704974 | U28: =+'NOTAS ERI'!R48 -> 25253559 | V28: =+'NOTAS ERI'!S48 -> 25200857 | W28: =+'NOTAS ERI'!T48 -> 24705084 | X28: =+'NOTAS ERI'!U48 -> 25034984 | Y28: =+'NOTAS ERI'!V48 -> 25453384 | Z28: =+'NOTAS ERI'!W48 -> 24717866 | AA28: =+'NOTAS ERI'!X48 -> 25225031 | ... AE28: =+'NOTAS ERI'!AB48 -> 4734864 | AG28: =SUM(AH28:AS28) -> 78133865 | AH28: =+'NOTAS ERI'!AE48 -> 4303506 | AI28: =+'NOTAS ERI'!AF48 -> 4303506 | AJ28: =+'NOTAS ERI'!AG48 -> 4568899 | AK28: =+'NOTAS ERI'!AH48 -> 6292759 | AL28: =+'NOTAS ERI'!AI48 -> 6292759 | AM28: =+'NOTAS ERI'!AJ48 -> 6292759 | AN28: =+'NOTAS ERI'!AK48 -> 6528793 | AO28: =+'NOTAS ERI'!AL48 -> 8282012 | ... AS28: =+'NOTAS ERI'!AP48 -> 6292760 | AU28: =SUM(AV28:BG28) -> 61808180 | AV28: =+'NOTAS ERI'!AS48 -> 5656536 | AW28: =+'NOTAS ERI'!AT48 -> 5587989 | AX28: =+'NOTAS ERI'!AU48 -> 5678706 | AY28: =+'NOTAS ERI'!AV48 -> 5204740 | AZ28: =+'NOTAS ERI'!AW48 -> 5628594 | BA28: =+'NOTAS ERI'!AX48 -> 3793838 | BB28: =+'NOTAS ERI'!AY48 -> 4758686 | BC28: =+'NOTAS ERI'!AZ48 -> 3793838 | ... BG28: =+'NOTAS ERI'!BD48 -> 5232130 | BI28: =+'NOTAS ERI'!BF48 -> 44303847 | BJ28: =+'NOTAS ERI'!BG48 -> 1751117.4 | BK28: =+'NOTAS ERI'!BH48 -> 7284177.5 | BL28: =+'NOTAS ERI'!BI48 -> 8335077.5 | BM28: =+'NOTAS ERI'!BJ48 -> 8396593.7 | BN28: =+'NOTAS ERI'!BK48 -> 5226039.7 | BO28: =+'NOTAS ERI'!BL48 -> 672313.55 | BP28: =+'NOTAS ERI'!BM48 -> 0 | ... BU28: =+'NOTAS ERI'!BR48 -> 3042927.4 | BW28: =+'NOTAS ERI'!BT48 -> 17377485 | BX28: =+'NOTAS ERI'!BU48 -> 17377485 | BY28: =+'NOTAS ERI'!BV48 -> 0 | BZ28: =+'NOTAS ERI'!BW48 -> 0 | CA28: =+'NOTAS ERI'!BX48 -> 0 | CB28: =+'NOTAS ERI'!BY48 -> 0 | CC28: =+'NOTAS ERI'!BZ48 -> 0 | CE28: =+'NOTAS ERI'!CB48 -> 0 | CF28: =+'NOTAS ERI'!#REF! -> #REF! | CH28: =+'NOTAS ERI'!#REF! -> #REF!
